Workbook

Sheet Geral
A2: PROTEÍNAS CLIENTE | B2: ESTOQUE | C2: MEDIDA | D2: VALOR (R$) | E2: TOTAL (R$) | F2: PEDIDO | G2: VALOR DO PEDIDO | H2: MERCEARIA | I2: ESTOQUE | J2: MEDIDA | K2: VALOR (R$) | L2: TOTAL (R$) | M2: PEDIDO | N2: VALOR DO PEDIDO | O2: CONGELADOS | P2: ESTOQUE | Q2: MEDIDA | R2: VALOR (R$) | S2: TOTAL (R$) | T2: PEDIDO | U2: VALOR DO PEDIDO | V2: DESCARTÁVEIS | W2: ESTOQUE | X2: MEDIDA | Y2: VALOR (R$) | Z2: TOTAL (R$) | AA2: PEDIDO | AB2: VALOR DO PEDIDO
A3: ACEM | B3: 16.3 | C3: KG | D3: 30.59 | E3: =B3*D3 -> 498.617 | F3: 0 | G3: =PRODUCT(D3,F3) -> 0 | H3: AMENDOIM SEM CASCA | I3: 0 | J3: KG | K3: 20 | L3: =I3*K3 -> 0 | M3: 0 | N3: 0 | O3: AIPIM CONGELADO (1KG) | P3: 35.5 | Q3: KG | R3: 15 | S3: =P3*R3 -> 532.5 | T3: 0 | U3: =PRODUCT(R3,T3) -> 0 | V3: BOBINA PICOTADA (20X30) | W3: 1 | X3: UND | Y3: 34.9 | Z3: =W3*Y3 -> 34.9 | AA3: 0 | AB3: =Y3*AA3 -> 0
A4: ASA DE FRANGO | B4: 0 | C4: KG | D4: 11.98 | E4: =B4*D4 -> 0 | F4: 0 | G4: =PRODUCT(D4,F4) -> 0 | H4: ABACAXI EM CONSERVA (400g) | I4: 0 | J4: UND | K4: 7.98 | L4: =I4*K4 -> 0 | M4: 0 | N4: =PRODUCT(K4,M4) -> 0 | O4: BATATA CONGELADA | P4: 49.12 | Q4: KG | R4: 13.38 | S4: =P4*R4 -> 657.2256 | T4: 0 | U4: =PRODUCT(R4,T4) -> 0 | V4: BOBINA PICOTADA (30X40) | W4: 5 | X4: UND | Y4: 66.49 | Z4: =W4*Y4 -> 332.45 | AA4: 0 | AB4: =Y4*AA4 -> 0
A5: BOMBOM DA ALCATRA | B5: 13.3 | C5: KG | D5: 69.66 | E5: =B5*D5 -> 926.478 | F5: 0 | G5: =PRODUCT(D5,F5) -> 0 | H5: ACETO BALSAMICO (500ml) | I5: 1 | J5: UND | K5: 12.9 | L5: =I5*K5 -> 12.9 | M5: 0 | N5: =PRODUCT(K5,M5) -> 0 | O5: ERVILHA CONGELADA | P5: 5.5 | Q5: KG | R5: 12.88 | S5: =P5*R5 -> 70.84 | T5: 0 | U5: 0 | V5: BOBINA PICOTADA (40X60) | W5: 2 | X5: UND | Y5: 42.53 | Z5: =W5*Y5 -> 85.06 | AA5: 0 | AB5: =Y5*AA5 -> 0
A6: BARRIGA MANTA | B6: 0 | C6: KG | D6: 0 | E6: =B6*D6 -> 0 | F6: 0 | G6: 0 | H6: BATATA PALHA | I6: 0 | J6: KG | K6: 5.19 | L6: =I6*K6 -> 0 | M6: 0 | N6: =PRODUCT(K6,M6) -> 0 | O6: MASSA PASTEL | P6: 50 | Q6: KG | R6: 7 | S6: =P6*R6 -> 350 | T6: 0 | U6: =PRODUCT(R6,T6) -> 0 | V6: BOBINA 29G 8X250mts | W6: 0 | X6: CX | Y6: 85.09 | Z6: =W6*Y6 -> 0 | AA6: 0 | AB6: =Y6*AA6 -> 0
A7: BARRIGA SUÍNA | B7: 20.45 | C7: KG | D7: 15.52 | E7: =B7*D7 -> 317.384 | F7: 0 | G7: =PRODUCT(D7,F7) -> 0 | H7: AÇUCAR REFINADO (1kg) | I7: 17 | J7: KG | K7: 3.35 | L7: =I7*K7 -> 56.95 | M7: 0 | N7: =PRODUCT(K7,M7) -> 0 | P7: 0 | Q7: KG | R7: 0 | S7: =P7*R7 -> 0 | T7: 0 | U7: =PRODUCT(R7,T7) -> 0 | V7: BOBINA TÉRMICA | W7: 2 | X7: CX | Y7: 98.9 | Z7: =W7*Y7 -> 197.8 | AA7: 0 | AB7: 0
A8: CARNE SECA LAGARTO | B8: 15 | C8: KG | D8: 47.9 | E8: =B8*D8 -> 718.5 | F8: 0 | G8: =PRODUCT(D8,F8) -> 0 | H8: AÇUCAR SACHÊ (2kg) | I8: 1 | J8: CX | K8: 17.29 | L8: =I8*K8 -> 17.29 | M8: 0 | N8: =PRODUCT(K8,M8) -> 0 | O8: GELO ESCAMA | P8: 31 | Q8: UND | R8: 10 | S8: =P8*R8 -> 310 | T8: 0 | U8: =PRODUCT(R8,T8) -> 0 | V8: CANUDO | W8: 8 | X8: PCT | Y8: 13.64 | Z8: =W8*Y8 -> 109.12 | AA8: 0 | AB8: =Y8*AA8 -> 0
A9: CARRÉ | B9: 0 | C9: KG | D9: 13.8 | E9: =B9*D9 -> 0 | F9: 0 | G9: =PRODUCT(D9,F9) -> 0 | H9: ADOÇANTE SACHÊ (2kg) | I9: 3 | J9: CX | K9: 74.05 | L9: =I9*K9 -> 222.15 | M9: 0 | N9: =PRODUCT(K9,M9) -> 0 | O9: GELO CUBO | P9: 15 | Q9: UND | R9: 10 | S9: =P9*R9 -> 150 | T9: 0 | U9: =PRODUCT(R9,T9) -> 0 | V9: MAÇARICO | W9: 1 | X9: UND | Y9: 29.9 | Z9: =W9*Y9 -> 29.9 | AA9: 0 | AB9: =Y9*AA9 -> 0
A10: CARNE MOÍDA ACÉM | B10: 15.35 | C10: KG | D10: 35.95 | E10: =B10*D10 -> 551.8325 | F10: 0 | G10: =PRODUCT(D10,F10) -> 0 | H10: AMIDO DE MILHO | I10: 0 | J10: KG | K10: 7 | L10: =I10*K10 -> 0 | M10: 0 | N10: =PRODUCT(K10,M10) -> 0 | V10: COLHER DESCARTÁVEL (C/200) | W10: 0 | X10: UND | Y10: 9.2 | Z10: =W10*Y10 -> 0 | AA10: 0 | AB10: =Y10*AA10 -> 0
A11: CARNE MOÍDA PEITO BOVINO | B11: 0 | C11: KG | D11: 0 | E11: =B11*D11 -> 0 | F11: 0 | G11: =PRODUCT(D11,F11) -> 0 | H11: ARROZ PARBOILIZADO | I11: 55 | J11: KG | K11: 3.92 | L11: =I11*K11 -> 215.6 | M11: 0 | N11: =PRODUCT(K11,M11) -> 0 | O11: TOTAL CONGELADOS: | S11: =SUM(S3:S9) -> 2070.5656 | U11: =SUM(U4:U6) -> 0 | V11: COPO DESCARTÁVEL (300ml) (pcts) | W11: 1 | X11: CX | Y11: 170.9 | Z11: =W11*Y11 -> 170.9 | AA11: 0 | AB11: =Y11*AA11 -> 0
A12: BUCHO | B12: 0 | C12: KG | D12: 13.64 | E12: =B12*D12 -> 0 | F12: 0 | G12: 0 | H12: AZEITE DE DENDE | I12: 8 | J12: UND | K12: 12.28 | L12: =I12*K12 -> 98.24 | M12: 0 | N12: =PRODUCT(K12,M12) -> 0 | V12: COPO DESCARTÁVEL (400ml) (pcts) | W12: 0 | X12: UND | Y12: 13.3 | Z12: =W12*Y12 -> 0 | AA12: 0 | AB12: =Y12*AA12 -> 0
A13: PERNIL | B13: 1.08 | C13: KG | D13: 13.9 | E13: =B13*D13 -> 15.012 | F13: 0 | G13: =PRODUCT(D13,F13) -> 0 | H13: AZEITE EXTRA VIRGEM (5lts) | I13: 1 | J13: UND | K13: 197.9 | L13: =I13*K13 -> 197.9 | M13: 0 | N13: =PRODUCT(K13,M13) -> 0 | O13: LATICÍNIOS | P13: ESTOQUE | Q13: MEDIDA | R13: VALOR (R$) | S13: TOTAL (R$) | T13: PEDIDO | U13: VALOR DO PEDIDO | V13: COPO DESCARTÁVEL (50ml) (pcts) | W13: 0 | X13: UND | Y13: 0 | Z13: =W13*Y13 -> 0 | AA13: 0 | AB13: =Y13*AA13 -> 0
A14: CONTRA FILÉ | B14: 11.5 | C14: KG | D14: 47.87 | E14: =B14*D14 -> 550.505 | F14: 0 | G14: =PRODUCT(D14,F14) -> 0 | H14: AZEITE EXTRA VIRGEM SACHÊ (180und.) | I14: 0 | J14: CX | K14: 49.5 | L14: =I14*K14 -> 0 | M14: 0 | N14: =PRODUCT(K14,M14) -> 0 | O14: CHOCOLATE MEIO AMARGO (NESTLE) (1KG) | P14: 0 | Q14: KG | R14: 68.21 | S14: =P14*R14 -> 0 | T14: 0 | U14: =PRODUCT(R14,T14) -> 0 | V14: COPO DESCARTÁVEL (25ml) (pcts) | W14: 0 | X14: UND | Y14: 0 | Z14: =W14*Y14 -> 0 | AA14: 0 | AB14: =Y14*AA14 -> 0
A15: COSTELA SALGADA | B15: 10 | C15: KG | D15: 17.38 | E15: =B15*D15 -> 173.8 | F15: 0 | G15: =PRODUCT(D15,F15) -> 0 | H15: AZEITE EXTRA VIRGEM O-LIVE (500ml) | I15: 17 | J15: UND | K15: 26.49 | L15: =I15*K15 -> 450.33 | M15: 0 | N15: =PRODUCT(K15,M15) -> 0 | O15: CHOCOLATE AO LEITE | P15: 0 | Q15: KG | R15: 0 | S15: =P15*R15 -> 0 | T15: 0 | U15: =PRODUCT(R15,T15) -> 0 | V15: DEDEIRA | W15: 0 | X15: PCT | Y15: 0 | Z15: =W15*Y15 -> 0 | AA15: 0 | AB15: =Y15*AA15 -> 0
A16: COXA E SOBRECOXA SEM OSSO | B16: 29.85 | C16: KG | D16: 7.42 | E16: =B16*D16 -> 221.487 | F16: 0 | G16: =PRODUCT(D16,F16) -> 0 | H16: AZEITONA SEM CAROÇO 2KG | I16: 2 | J16: UND | K16: 56.9 | L16: =I16*K16 -> 113.8 | M16: 0 | N16: =PRODUCT(K16,M16) -> 0 | O16: CHOCOLATE MARFIM | P16: 0 | Q16: KG | R16: 0 | S16: =P16*R16 -> 0 | T16: 0 | U16: =PRODUCT(R16,T16) -> 0 | V16: ETIQUETA LISA | W16: 0 | X16: UND | Y16: 19 | Z16: =W16*Y16 -> 0 | AA16: 0 | AB16: =Y16*AA16 -> 0
A17: COXÃO MOLE | B17: 0 | C17: KG | D17: 36.59 | E17: =B17*D17 -> 0 | F17: 0 | G17: 0 | H17: AZEITONA VERDE | I17: 0 | J17: KG | K17: 25.45 | L17: =I17*K17 -> 0 | M17: 0 | N17: =PRODUCT(K17,M17) -> 0 | O17: CREAM CHEESE (1,2kg) | P17: 0 | Q17: KG | R17: 20 | S17: =P17*R17 -> 0 | T17: 0 | U17: =PRODUCT(R17,T17) -> 0 | V17: ETIQUETA USAR PRIMEIRO | W17: 0 | X17: UND | Y17: 25 | Z17: =W17*Y17 -> 0 | AA17: 0 | AB17: =Y17*AA17 -> 0
A18: COSTELA BOVINA | B18: 3.55 | C18: KG | D18: 20.71 | E18: =B18*D18 -> 73.5205 | F18: 0 | G18: =PRODUCT(D18,F18) -> 0 | H18: CAFÉ FUNCIONÁRIO (500g) | I18: 1 | J18: KG | K18: 57.11 | L18: =I18*K18 -> 57.11 | M18: 0 | N18: =PRODUCT(K18,M18) -> 0 | O18: CHEDDAR FATIADO | P18: 0 | Q18: KG | R18: 36.5 | S18: =P18*R18 -> 0 | T18: 0 | U18: 0 | V18: ETIQUETA RASTREABILIDADE (60X40) (C/1000) | W18: 0 | X18: UND | Y18: 70 | Z18: =W18*Y18 -> 0 | AA18: 0 | AB18: =Y18*AA18 -> 0
A19: DRUMET | B19: 0 | C19: KG | D19: 9.76 | E19: =B19*D19 -> 0 | F19: 0 | G19: =PRODUCT(D19,F19) -> 0 | H19: CHAMPIGNON | I19: 0 | J19: KG | K19: 38.49 | L19: =I19*K19 -> 0 | M19: 0 | N19: =PRODUCT(K19,M19) -> 0 | O19: CREME DE LEITE | P19: 13 | Q19: UND | R19: 12.89 | S19: =P19*R19 -> 167.57 | T19: 0 | U19: =PRODUCT(R19,T19) -> 0 | V19: ETIQUETA SEGURANÇA ALIMENTAR | W19: 0 | X19: UND | Y19: 38 | Z19: =W19*Y19 -> 0 | AA19: 0 | AB19: =Y19*AA19 -> 0
A20: FIGADO | B20: 0 | C20: KG | D20: 8.43 | E20: =B20*D20 -> 0 | F20: 0 | G20: =PRODUCT(D20,F20) -> 0 | H20: CAFÉ CAPSULA | I20: 129 | J20: KG | K20: 2.35 | L20: =I20*K20 -> 303.15 | M20: 0 | N20: =PRODUCT(K20,M20) -> 0 | O20: LEITE INTEGRAL (1lts) | P20: 15 | Q20: UND | R20: 5.7 | S20: =P20*R20 -> 85.5 | T20: 0 | U20: =PRODUCT(R20,T20) -> 0 | V20: ETIQUETA DE VALIDADE | W20: 0 | X20: UND | Y20: 43.6 | Z20: =W20*Y20 -> 0 | AA20: 0 | AB20: 0
A21: FILÉ MIGNON | B21: 0 | C21: KG | D21: 0 | E21: =B21*D21 -> 0 | F21: 0 | G21: =PRODUCT(D21,F21) -> 0 | H21: CALDO DE CARNE | I21: 3 | J21: KG | K21: 9.59 | L21: =I21*K21 -> 28.77 | M21: 0 | N21: =PRODUCT(K21,M21) -> 0 | O21: LEITE DE COCO | P21: 7 | Q21: UND | R21: 19.63 | S21: =P21*R21 -> 137.41 | T21: 0 | U21: =PRODUCT(R21,T21) -> 0 | V21: ESPETO PARA CHURRASCO (pcts) | W21: 11 | X21: PCT | Y21: 5.2 | Z21: =W21*Y21 -> 57.2 | AA21: 0 | AB21: =Y21*AA21 -> 0
A22: ORELHA DE PORCO | B22: 11.35 | C22: KG | D22: 8.83 | E22: =B22*D22 -> 100.2205 | F22: 0 | G22: =PRODUCT(D22,F22) -> 0 | H22: CALDO DE GALINHA (1,01kg) | I22: 3.75 | J22: KG | K22: 9.59 | L22: =I22*K22 -> 35.9625 | M22: 0 | N22: =PRODUCT(K22,M22) -> 0 | O22: LEITE CONDENSADO (395ml) | P22: 9 | Q22: UND | R22: 5.69 | S22: =P22*R22 -> 51.21 | T22: 0 | U22: =PRODUCT(R22,T22) -> 0 | V22: EMBALAGEM 30ml | W22: 0 | X22: UND | Y22: 162 | Z22: =W22*Y22 -> 0 | AA22: 0 | AB22: =Y22*AA22 -> 0
A23: GARGANTA SALGADA | B23: 0 | C23: KG | D23: 5.5 | E23: =B23*D23 -> 0 | F23: 0 | G23: =PRODUCT(D23,F23) -> 0 | H23: CAPSULA DE CHANTILY | I23: 11 | J23: UND | K23: 21.98 | L23: =I23*K23 -> 241.78 | M23: 0 | N23: =PRODUCT(K23,M23) -> 0 | O23: LEITE CONDENSADO (2,6kg) | P23: 0 | Q23: KG | R23: 11.12 | S23: =P23*R23 -> 0 | T23: 0 | U23: =PRODUCT(R23,T23) -> 0 | V23: EMBALAGEM 250ML | W23: 0 | X23: UND | Y23: 0.60513888 | Z23: =W23*Y23 -> 0 | AA23: 0 | AB23: =Y23*AA23 -> 0
A24: LAGARTO | B24: 0 | C24: KG | D24: 31.79 | E24: =B24*D24 -> 0 | F24: 0 | G24: =PRODUCT(D24,F24) -> 0 | H24: CHIMICHURRI | I24: 0 | J24: KG | K24: 45 | L24: =I24*K24 -> 0 | M24: 0 | N24: =PRODUCT(K24,M24) -> 0 | O24: MANTEIGA DE GARRAFA 460KG | P24: 0 | Q24: KG | R24: 28 | S24: =P24*R24 -> 0 | T24: 0 | U24: =PRODUCT(R24,T24) -> 0 | V24: EMBALAGEM 500ml (PRAFESTA) | W24: 0 | X24: CX | Y24: 75.31 | Z24: =W24*Y24 -> 0 | AA24: 0 | AB24: =Y24*AA24 -> 0
A25: LOMBO SUÍNO SALGADO | B25: 4.3 | C25: KG | D25: 17.65 | E25: =B25*D25 -> 75.895 | F25: 0 | G25: =PRODUCT(D25,F25) -> 0 | H25: EMULSIFICANTE | I25: 3 | J25: KG | K25: 25.42 | L25: =I25*K25 -> 76.26 | M25: 0 | N25: =PRODUCT(K25,M25) -> 0 | O25: MANTEIGA COM SAL | P25: 0 | Q25: KG | R25: 32.4 | S25: =P25*R25 -> 0 | T25: 0 | U25: =PRODUCT(R25,T25) -> 0 | V25: EMBALAGEM 750ML (PRA FESTA) C/24 | W25: 3 | X25: PCT | Y25: 34.68 | Z25: =W25*Y25 -> 104.04 | AA25: 0 | AB25: =Y25*AA25 -> 0
A26: MOCOTÓ | B26: 0 | C26: KG | D26: 7.88 | E26: =B26*D26 -> 0 | F26: 0 | G26: =PRODUCT(D26,F26) -> 0 | H26: ERVILHA SECA | I26: 2 | J26: KG | K26: 5.9 | L26: =I26*K26 -> 11.8 | M26: 0 | N26: =PRODUCT(K26,M26) -> 0 | O26: MANTEIGA SEM SAL | P26: 0 | Q26: KG | R26: 24 | S26: =P26*R26 -> 0 | T26: 0 | U26: =PRODUCT(R26,T26) -> 0 | V26: EMBALAGEM ALUMINIO 500ML (P1380) | W26: 0 | X26: UND | Y26: 0.81 | Z26: =W26*Y26 -> 0 | AA26: 0 | AB26: =Y26*AA26 -> 0
A27: MÚSCULO | B27: 0 | C27: KG | D27: 26.86 | E27: =B27*D27 -> 0 | F27: 0 | G27: =PRODUCT(D27,F27) -> 0 | H27: EXTRATO DE TOMATE | I27: 2 | J27: KG | K27: 23.99 | L27: =I27*K27 -> 47.98 | M27: 0 | N27: =PRODUCT(K27,M27) -> 0 | O27: MARGARINA QUALY (500g) | P27: 16 | Q27: KG | R27: 7.98 | S27: =P27*R27 -> 127.68 | T27: 0 | U27: =PRODUCT(R27,T27) -> 0 | V27: EMBALAGEM ALUMINIO 750ML | W27: 0 | X27: CX | Y27: 167 | Z27: =W27*Y27 -> 0 | AA27: 0 | AB27: =Y27*AA27 -> 0
A28: PÉ DE PORCO | B28: 5.75 | C28: KG | D28: 9.7 | E28: =B28*D28 -> 55.775 | F28: 0 | G28: =PRODUCT(D28,F28) -> 0 | H28: FARINHA DE MANDIOCA (1kg) | I28: 19 | J28: KG | K28: 5.37 | L28: =I28*K28 -> 102.03 | M28: 0 | N28: =PRODUCT(K28,M28) -> 0 | O28: MUSSARELA FATIADA | P28: 0 | Q28: KG | R28: 33.98 | S28: =P28*R28 -> 0 | T28: 0 | U28: =PRODUCT(R28,T28) -> 0 | V28: FILME PVC (28X300) | W28: 1 | X28: UND | Y28: 28.2 | Z28: =W28*Y28 -> 28.2 | AA28: 0 | AB28: =Y28*AA28 -> 0
A29: PEITO DE FRANGO | B29: 18.7 | C29: KG | D29: 12.84 | E29: =B29*D29 -> 240.108 | F29: 0 | G29: =PRODUCT(D29,F29) -> 0 | H29: FARINHA PANKO (1kg) | I29: 27 | J29: KG | K29: 16.2 | L29: =I29*K29 -> 437.4 | M29: 0 | N29: =PRODUCT(K29,M29) -> 0 | O29: MUSSARELA RALADA | P29: 0 | Q29: KG | R29: 33.98 | S29: =P29*R29 -> 0 | T29: 0 | U29: =PRODUCT(R29,T29) -> 0 | V29: FILME PVC (40cm) | W29: 0 | X29: UND | Y29: 76.2 | Z29: =W29*Y29 -> 0 | AA29: 0 | AB29: =Y29*AA29 -> 0
A30: LOMBO SUÍNO | B30: 0 | C30: KG | D30: 18.9 | E30: =B30*D30 -> 0 | F30: 0 | G30: =PRODUCT(D30,F30) -> 0 | H30: FARINHA DE ROSCA (1kg) | I30: 0 | J30: KG | K30: 4.1 | L30: =I30*K30 -> 0 | M30: 0 | N30: 0 | O30: MUSSARELA COMUM | P30: 10.62 | Q30: KG | R30: 33.98 | S30: =P30*R30 -> 360.8676 | T30: 0 | U30: =PRODUCT(R30,T30) -> 0 | V30: FOSFORO | W30: 0 | X30: UND | Y30: 4.23 | Z30: =W30*Y30 -> 0 | AA30: 0 | AB30: =Y30*AA30 -> 0
A31: TOUCINHO | B31: 26 | C31: KG | D31: 17.95 | E31: =B31*D31 -> 466.7 | F31: 0 | G31: =PRODUCT(D31,F31) -> 0 | H31: FARINHA DE ROSCA (5kg) | I31: 1 | J31: KG | K31: 7.7 | L31: =I31*K31 -> 7.7 | M31: 0 | N31: =PRODUCT(K31,M31) -> 0 | O31: PARMESÃO COZINHA | P31: 4 | Q31: KG | R31: 45.5 | S31: =P31*R31 -> 182 | T31: 0 | U31: =PRODUCT(R31,T31) -> 0 | V31: GÁS PARA MAÇARICO | W31: 27 | X31: UND | Y31: 13.45 | Z31: =W31*Y31 -> 363.15 | AA31: 0 | AB31: =Y31*AA31 -> 0
A32: RABADA | B32: 0 | C32: KG | D32: 16.45 | E32: =B32*D32 -> 0 | F32: 0 | G32: =PRODUCT(D32,F32) -> 0 | H32: FARINHA DE TRIGO (1kg) | I32: 19 | J32: KG | K32: 4.1 | L32: =I32*K32 -> 77.9 | M32: 0 | N32: =PRODUCT(K32,M32) -> 0 | O32: PRESUNTO COZIDO | P32: 3.5 | Q32: KG | R32: 19.5 | S32: =P32*R32 -> 68.25 | T32: 0 | U32: =PRODUCT(R32,T32) -> 0 | V32: GUARDANAPO CREP 29X29 | W32: 0 | X32: CX | Y32: 99 | Z32: =W32*Y32 -> 0 | AA32: 0 | AB32: =Y32*AA32 -> 0
H33: FEIJÃO BRANCO | I33: 0 | J33: KG | K33: 10.99 | L33: =I33*K33 -> 0 | M33: 0 | N33: =PRODUCT(K33,M33) -> 0 | O33: QUEIJO COALHO (2kg) | P33: 5.33 | Q33: KG | R33: 42 | S33: =P33*R33 -> 223.86 | T33: 0 | U33: =PRODUCT(R33,T33) -> 0 | V33: GUARDANAPO | W33: 0 | X33: CXS | Y33: 110.85 | Z33: =W33*Y33 -> 0 | AA33: 0 | AB33: =Y33*AA33 -> 0
E34: =SUM(E3:E32) -> 4985.8345 | G34: =SUM(G7:G32) -> 0 | H34: FEIJÃO FRADINHO | I34: 3 | J34: KG | K34: 6.98 | L34: =I34*K34 -> 20.94 | M34: 0 | N34: =PRODUCT(K34,M34) -> 0 | O34: QUEIJO DE CABRA | P34: 0 | Q34: KG | R34: 0 | S34: =P34*R34 -> 0 | T34: 0 | U34: =PRODUCT(R34,T34) -> 0 | V34: GUARDANAPO DADU | W34: 2 | X34: CX | Y34: 108.9 | Z34: =W34*Y34 -> 217.8 | AA34: 0 | AB34: =Y34*AA34 -> 0
H35: FEIJÃO VERMELHO | I35: 2 | J35: KG | K35: 8.69 | L35: =I35*K35 -> 17.38 | M35: 0 | N35: 0 | O35: QUEIJO CHEDDAR | P35: 5.6 | Q35: KG | R35: 36.5 | S35: =P35*R35 -> 204.4 | T35: 0 | U35: =PRODUCT(R35,T35) -> 0 | V35: GUARDANAPO SACHÊ (20x17) | W35: 0 | X35: PCT | Y35: 36.45 | Z35: =W35*Y35 -> 0 | AA35: 0 | AB35: =Y35*AA35 -> 0
A36: PROTEÍNAS FUNCIONÁRIO | B36: ESTOQUE | C36: MEDIDA | D36: VALOR (R$) | E36: TOTAL (R$) | F36: PEDIDO | G36: VALOR PEDIDO | H36: FEIJÃO PRETO (1kg) | I36: 19 | J36: KG | K36: 5.89 | L36: =I36*K36 -> 111.91 | M36: 0 | N36: =PRODUCT(K36,M36) -> 0 | O36: QUEIJO TROPICAL ORIENTE | P36: 0 | Q36: KG | R36: 45.5 | S36: =P36*R36 -> 0 | T36: 0 | U36: =PRODUCT(R36,T36) -> 0 | V36: LUVAS DE VINIL | W36: 4 | X36: CX | Y36: 26.5 | Z36: =W36*Y36 -> 106 | AA36: 0 | AB36: =Y36*AA36 -> 0
A37: COXA E SOBRECOXA | B37: 0 | C37: KG | D37: 7.38 | E37: =B37*D37 -> 0 | F37: 0 | G37: =D37*F37 -> 0 | H37: FÚBA | I37: 0 | J37: KG | K37: 3.5 | L37: =I37*K37 -> 0 | M37: 0 | N37: 0 | O37: QUEIJO PRATO GRAN NATO | P37: 0 | Q37: KG | R37: 29.98 | S37: =P37*R37 -> 0 | T37: 0 | U37: =PRODUCT(R37,T37) -> 0 | V37: MÁSCARA DESCARTÁVEL (PCT) | W37: 0 | X37: CX | Y37: 19.5 | Z37: =W37*Y37 -> 0 | AA37: 0 | AB37: =Y37*AA37 -> 0
A38: SALSICHA | B38: 0 | C38: KG | D38: 9.28 | E38: =B38*D38 -> 0 | F38: 0 | G38: =D38*F38 -> 0 | H38: FERMENTO (250g) | I38: 0 | J38: UND | K38: 19.75 | L38: =I38*K38 -> 0 | M38: 0 | N38: =PRODUCT(K38,M38) -> 0 | O38: QUEIJO PRATO FATIADO (150g) | P38: 0 | Q38: KG | R38: 27.49 | S38: =P38*R38 -> 0 | T38: 0 | U38: =PRODUCT(R38,T38) -> 0 | V38: PALITO DE BAMBU (9CM) | W38: 4 | X38: PCT | Y38: 18.49 | Z38: =W38*Y38 -> 73.96 | AA38: 0 | AB38: =Y38*AA38 -> 0
H39: GOIABADA 2,5 KG | I39: 3.69 | J39: UND | K39: 26.95 | L39: =I39*K39 -> 99.4455 | M39: 0 | N39: =PRODUCT(K39,M39) -> 0 | O39: QUEIJO PROVOLONE | P39: 0 | Q39: KG | R39: 29.5 | S39: =P39*R39 -> 0 | T39: 0 | U39: =PRODUCT(R39,T39) -> 0 | V39: PALITO DE CHURRASCO | W39: 0 | X39: PCT | Y39: 5.2 | Z39: =W39*Y39 -> 0 | AB39: =Y39*AA39 -> 0
A40: TOTAL PROTEÍNAS FUNCIONÁRIO: | E40: =SUM(E37,E38) -> 0 | G40: =SUM(G24:G37) -> 0 | H40: KETCHUP | I40: 2 | J40: UND | K40: 27.58 | L40: =I40*K40 -> 55.16 | M40: 0 | N40: =PRODUCT(K40,M40) -> 0 | O40: QUEIJO PARMESÃO | P40: 0 | Q40: KG | R40: 45.5 | S40: =P40*R40 -> 0 | T40: 0 | U40: =PRODUCT(R40,T40) -> 0 | V40: PALITO DE DENTE (CX) | W40: 1 | X40: UND | Y40: 14.29 | Z40: =W40*Y40 -> 14.29 | AA40: 0 | AB40: =Y40*AA40 -> 0
H41: KETCHUP SACHÊ (2kg) | I41: 4 | J41: CX | K41: 21.53 | L41: =I41*K41 -> 86.12 | M41: 0 | N41: =PRODUCT(K41,M41) -> 0 | O41: REQUEIJÃO | P41: 0 | Q41: KG | R41: 0 | S41: =P41*R41 -> 0 | T41: 0 | U41: =PRODUCT(R41,T41) -> 0 | V41: PAPEL ALUMINIO | W41: 1 | X41: UND | Y41: 49.56 | Z41: =W41*Y41 -> 49.56 | AA41: 0 | AB41: =Y41*AA41 -> 0
...

Sheet Hortifruti
A1: HORTIFRUTI BAR DO ZECA
A2: PRODUTOS | B2: ESTOQUE | C2: MEDIDA | D2: VALOR (R$) | E2: TOTAL (R$) | F2: PEDIDO | G2: VALOR DO PEDIDO
A3: ABACATE AVOCADO | B3: 0 | C3: KG | D3: 49.9 | E3: =D3*B3 -> 0 | F3: 0 | G3: =D3*F3 -> 0
A4: ABACAXI | B4: 1.32 | C4: KG | D4: 9.58 | E4: =D4*B4 -> 12.6456 | F4: 0 | G4: =D4*F4 -> 0
A5: ABÓBORA | B5: 0 | C5: KG | D5: 5 | E5: =D5*B5 -> 0 | F5: 0 | G5: 0
A6: ABÓBORA JAPONÊSA | B6: 2.9 | C6: KG | D6: 16.13 | E6: =D6*B6 -> 46.777 | F6: 0 | G6: =D6*F6 -> 0
A7: ABOBRINHA | B7: 0.48 | C7: KG | D7: 4.05 | E7: =D7*B7 -> 1.944 | F7: 0 | G7: =D7*F7 -> 0
A8: ACELGA | B8: 0 | C8: UN | D8: 2.85 | E8: =D8*B8 -> 0 | F8: 0 | G8: =D8*F8 -> 0
A9: AGRIÃO | B9: 0 | C9: UND | D9: 10.75 | E9: =D9*B9 -> 0 | F9: 0 | G9: =D9*F9 -> 0
A10: AIPIM | B10: 0 | C10: KG | D10: 10.08 | E10: =D10*B10 -> 0 | F10: 0 | G10: =D10*F10 -> 0
A11: AIPO | B11: 0 | C11: UN | D11: 89.71 | E11: =D11*B11 -> 0 | F11: 0 | G11: =D11*F11 -> 0
A12: ALECRIM | B12: 0.07 | C12: KG | D12: 35.5 | E12: =D12*B12 -> 2.485 | F12: 0 | G12: =D12*F12 -> 0
A13: ALFACE AMERICANA | B13: 3 | C13: KG | D13: 8.16 | E13: =D13*B13 -> 24.48 | F13: 0 | G13: =D13*F13 -> 0
A14: ALFACE CRESPA ROXA | B14: 0.31 | C14: KG | D14: 15.81 | E14: =D14*B14 -> 4.9011 | F14: 0 | G14: =D14*F14 -> 0
A15: ALFACE CRESPA VERDE | B15: 0.53 | C15: KG | D15: 16.76 | E15: =D15*B15 -> 8.8828 | F15: 0 | G15: =D15*F15 -> 0
A16: ALFACE ROMANA | B16: 0 | C16: KG | D16: 18.9 | E16: =D16*B16 -> 0 | F16: 0 | G16: =D16*F16 -> 0
A17: ALHO DESCASCADO | B17: 3.83 | C17: KG | D17: 20.86 | E17: =D17*B17 -> 79.8938 | F17: 0 | G17: =D17*F17 -> 0
... A31: BETERRABA | B31: 6.13 | C31: KG | D31: 5.84 | E31: =D31*B31 -> 35.7992 | F31: 0 | G31: =D31*F31 -> 0
A32: BROCOLIS | B32: 0 | C32: UN | D32: 11 | E32: =D32*B32 -> 0
A33: BRÓCOLIS AMERICANO | B33: 1.33 | C33: UN | D33: 19.9 | E33: =D33*B33 -> 26.467 | F33: 0 | G33: =D33*F33 -> 0
A34: CAPIM LIMAO | B34: 0 | C34: KG | D34: 36 | E34: =D34*B34 -> 0 | F34: 0 | G34: =D34*F34 -> 0
A35: CARAMBOLA | B35: 0 | C35: BDJ | D35: 15 | E35: =D35*B35 -> 0 | F35: 0 | G35: =D35*F35 -> 0
A36: CEBOLA | B36: 6.065 | C36: KG | D36: 4.46 | E36: =D36*B36 -> 27.0499 | F36: 0 | G36: =D36*F36 -> 0
A37: CEBOLA CALABRESA | B37: 0 | C37: KG | D37: 2.89 | E37: =D37*B37 -> 0 | F37: 0 | G37: =D37*F37 -> 0
A38: CEBOLA ROXA | B38: 2.8 | C38: KG | D38: 7.37 | E38: =D38*B38 -> 20.636 | F38: 0 | G38: =D38*F38 -> 0
A39: CEBOLETE | B39: 0 | C39: UND | D39: 2.4 | E39: =D39*B39 -> 0 | F39: 0 | G39: =D39*F39 -> 0
A40: CEBOLINHA | B40: 0 | C40: UN | D40: 16.87 | E40: =D40*B40 -> 0 | F40: 0 | G40: =D40*F40 -> 0
A41: CENOURA | B41: 1.18 | C41: KG | D41: 7.21 | E41: =D41*B41 -> 8.5078 | F41: 0 | G41: =D41*F41 -> 0
A42: CHUCHU | B42: 0 | C42: KG | D42: 7.9 | E42: =D42*B42 -> 0 | F42: 0 | G42: =D42*F42 -> 0
A43: COCO SECO | B43: 0 | C43: KG | D43: 8.12 | E43: =D43*B43 -> 0 | F43: 0 | G43: =D43*F43 -> 0
A44: COENTRO | B44: 0.12 | C44: UN | D44: 25.24 | E44: =D44*B44 -> 3.0288 | F44: 0 | G44: =D44*F44 -> 0
... A46: COUVE MANTEIGA | B46: 0 | C46: UN | D46: 11.14 | E46: =D46*B46 -> 0 | F46: 0 | G46: =D46*F46 -> 0
A47: ENDRO | B47: 0 | C47: UND | D47: 2.48 | E47: =D47*B47 -> 0 | F47: 0 | G47: 0
A48: ERVILHA TORTA | B48: 0 | C48: KG | D48: 37.9 | E48: =D48*B48 -> 0 | F48: 0 | G48: =D48*F48 -> 0
A49: ESTRAGÃO | B49: 0 | C49: UN | D49: 2.5 | E49: =D49*B49 -> 0 | F49: 0 | G49: =D49*F49 -> 0
A50: GENGIBRE | B50: 5.23 | C50: KG | D50: 8.12 | E50: =D50*B50 -> 42.4676 | F50: 0 | G50: =D50*F50 -> 0
A51: GRAPEFRUIT | B51: 0 | C51: KG | D51: 55 | E51: =D51*B51 -> 0 | F51: 0 | G51: =D51*F51 -> 0
A52: HORTELÃ | B52: 0 | C52: UN | D52: 15.2 | E52: =D52*B52 -> 0 | F52: 0 | G52: =D52*F52 -> 0
A53: INHAME | B53: 0 | C53: KG | D53: 12.5 | E53: =D53*B53 -> 0 | F53: 0 | G53: =D53*F53 -> 0
A54: KIWI | B54: 0 | C54: KG | D54: 37.5 | E54: =D54*B54 -> 0 | F54: 0 | G54: =D54*F54 -> 0
...

Sheet Massas
A1: CONTROLE DE ESTOQUE MASSAS
A2: MASSAS | B2: PORÇAO | C2: UND | D2: VALOR (R$) | E2: TOTAL (R$)
A3: BAGUETE (25g) | B3: 0 | C3: 0 | D3: 0.86 | E3: =SUM(B3+C3)*D3 -> 0
A4: BAGUETE (50g) (ITALIANO) | B4: 0 | C4: 0 | D4: 10.5 | E4: =SUM(B4+C4)*D4 -> 0
A5: BAGUETE (80g) | B5: 0 | C5: 0 | D5: 9 | E5: =SUM(B5+C5)*D5 -> 0
A6: BAGUETE 200GR | B6: 0 | C6: 0 | D6: 0.98 | E6: =SUM(B6+C6)*D6 -> 0
A7: BATATA FRITA (300g) | B7: 0 | C7: 0 | D7: 7.75 | E7: =SUM(B7+C7)*D7 -> 0
A8: BOLINHO DE AIPIM COM QUEIJO | B8: 17 | C8: 0 | D8: 7.38 | E8: =SUM(B8+C8)*D8 -> 125.46
A9: BOLINHO DE ARROZ | B9: 0 | C9: 0 | D9: 0.75 | E9: =SUM(B9+C9)*D9 -> 0
A10: BOLINHO DE BACALHAU | B10: 26 | C10: 0 | D10: 15.8 | E10: =SUM(B10+C10)*D10 -> 410.8
A11: BOLO DE CENOURA | B11: 0 | C11: 0 | D11: 2.6 | E11: =SUM(B11+C11)*D11 -> 0
A12: BOLOVO | B12: 0 | C12: 0 | D12: 0 | E12: =SUM(B12+C12)*D12 -> 0
A13: BRIOCHE | B13: 0 | C13: 0 | D13: 0.75 | E13: =SUM(B13+C13)*D13 -> 0
A14: CANELONE | B14: 0 | C14: 0 | D14: 9.8 | E14: =SUM(B14+C14)*D14 -> 0
... A48: RONDELE DE PRESUNTO E QUEIJO | B48: 0 | C48: 0 | D48: 3.6 | E48: =SUM(B48+C48)*D48 -> 0
A49: TOTAL | E49: =SUM(E3:E48) -> 1058.56

Sheet Porcionados
A1: PORCIONADOS BAR DO ZECA
A2: CARNES | B2: PORÇÕES | C2: ESTOQUE/KG | D2: VALOR (R$) | E2: TOTAL (R$)
A3: ACÉM DESFIADA 150 GR | B3: 0 | C3: 0 | D3: 5.85 | E3: =SUM(B3+C3)*D3 -> 0
A4: ACÉM DESFIADA 50 GR | B4: 26 | C4: 0 | D4: 3.44 | E4: =SUM(B4+C4)*D4 -> 89.44
A5: AIPIM TRITURADO | B5: 0 | C5: 0 | D5: 10.23 | E5: =SUM(B5+C5)*D5 -> 0
A6: AIPIM 300GR | B6: 16 | C6: 0 | D6: 4.2 | E6: =SUM(B6+C6)*D6 -> 67.2
A7: AIPIM COZIDO 1KG | B7: 0 | C7: 0 | D7: 15 | E7: =SUM(B7+C7)*D7 -> 0
A8: APERITIVO DE CARNE (ALCATRA) | B8: 0 | C8: 0 | D8: 23.24 | E8: =SUM(B8+C8)*D8 -> 0
A9: ARRIBA | B9: 0 | C9: 0 | D9: 7.39 | E9: =SUM(B9+C9)*D9 -> 0
A10: CARNE ASSADA (150G) | B10: 0 | C10: 0 | D10: 7.6 | E10: =SUM(B10+C10)*D10 -> 0
A11: CARNE ASSADA INTEIRA (TÁBUA DO BAR) | B11: 0 | C11: 0 | D11: 53.76 | E11: =SUM(B11+C11)*D11 -> 0
A12: CARNE ASSADA SANDUICHE (120g) | B12: 15 | C12: 0 | D12: 7.97 | E12: =SUM(B12+C12)*D12 -> 119.55
A13: CARNE DE HAMBURGUER 100g | B13: 23 | C13: 0 | D13: 1.4 | E13: =SUM(B13+C13)*D13 -> 32.2
A14: CARNE DE SOL | B14: 0 | C14: 0 | D14: 0 | E14: =SUM(B14+C14)*D14 -> 0
... A54: SANDUÍCHE DE LINGUIÇA(120G) | B54: 0 | C54: 0 | D54: 4.91 | E54: =SUM(B54+C54)*D54 -> 0
A55: TOTAL | E55: =SUM(E3:E54) -> 1184.5303
A56: APARAS | D56: VALOR (R$) | E56: TOTAL (R$)
A57: APARA DE CARNE | B57: 0 | C57: 0 | D57: 30.48 | E57: =SUM(B57+C57)*D57 -> 0
A58: APARA DE CONTRA FILÉ | B58: 0 | C58: 0 | D58: 34.98 | E58: =SUM(B58+C58)*D58 -> 0
A59: APARA DE CARNE ASSADA | B59: 0 | C59: 0 | D59: 21.75 | E59: =SUM(B59+C59)*D59 -> 0
A60: APARA DE COSTELA | B60: 0 | C60: 0 | D60: 0 | E60: =SUM(B60+C60)*D60 -> 0
A61: APARA DE PERNIL | B61: 0 | C61: 0 | D61: 0 | E61: =SUM(B61+C61)*D61 -> 0
A62: APARA DE FRANGO | B62: 0 | C62: 0 | D62: 6 | E62: =SUM(B62+C62)*D62 -> 0
A63: APARA DE LINGUIÇA | B63: 0 | C63: 0 | D63: 0 | E63: =SUM(B63+C63)*D63 -> 0
A64: APARA DE PERNIL | B64: 0 | C64: 0 | D64: 0 | E64: =SUM(B64+C64)*D64 -> 0
A65: TOTAL | E65: =SUM(E57:E64) -> 0
A66: PEIXES E FRUTOS DO MAR | B66: PORÇÕES | C66: KG | D66: VALOR (R$) | E66: TOTAL (R$)
A67: BACALHAU | B67: 0 | C67: 0 | D67: 83.2 | E67: =SUM(B67+C67)*D67 -> 0
A68: BACALHAU DESFIADO | B68: 0 | C68: 0 | D68: 49.1 | E68: =SUM(B68+C68)*D68 -> 0
A69: CAMARÃO 80 GR | B69: 0 | C69: 0 | D69: 5.8 | E69: =SUM(B69+C69)*D69 -> 0
A70: CAMARÃO 120 GR | B70: 7 | C70: 0 | D70: 8.7 | E70: =SUM(B70+C70)*D70 -> 60.9
A71: FILÉ DE TILÁPIA | B71: 17 | C71: 0 | D71: 6.34 | E71: =SUM(B71+C71)*D71 -> 107.78
A72: TILÁPIA DESFIADA | B72: 0 | C72: 0 | D72: 35.9 | E72: =SUM(B72+C72)*D72 -> 0
A73: TAMBORIL | B73: 0 | C73: 0 | D73: 0 | E73: =SUM(B73+C73)*D73 -> 0
A74: ISCA DE TILÁPIA (200g) | B74: 8 | C74: 0 | D74: 8.76 | E74: =SUM(B74+C74)*D74 -> 70.08
A75: TOTAL | E75: =SUM(E67:E74) -> 238.76
A76: SUÍNOS | B76: PORÇÕES | C76: KG | D76: VALOR (R$) | E76: TOTAL (R$)
A77: BACON | B77: 0 | C77: 0 | D77: 25.75 | E77: =SUM(B77+C77)*D77 -> 0
A78: BARRIGA SUÍNA | B78: 0 | C78: 0 | D78: 21.85 | E78: =SUM(B78+C78)*D78 -> 0
A79: COSTELA SUÍNA SALGADA | B79: 0 | C79: 0 | D79: 24.9 | E79: =SUM(B79+C79)*D79 -> 0
...

Sheet Molhos
A1: CONTROLE DE ESTOQUE MOLHOS BAR DO ZECA
A2: MOLHOS | B2: PORÇÕES | C2: ESTOQUE/KG | D2: VALOR (R$) | E2: TOTAL (R$)
A3: BARBECUE DE GOIABADA 600GR | B3: 8 | C3: 0 | D3: 17.08 | E3: =SUM(B3+C3)*D3 -> 136.64
A4: BOBO DE CAMARÃO 400gr | B4: 0 | C4: 4.93 | D4: 14.06 | E4: =SUM(B4+C4)*D4 -> 69.3158
A5: CALDO DE CAMARÃO | B5: 0 | C5: 0 | D5: 0 | E5: =SUM(B5+C5)*D5 -> 0
A6: CALDO DE CARNE | B6: 0 | C6: 1.85 | D6: 3 | E6: =SUM(B6+C6)*D6 -> 5.55
A7: CALDO DE COSTELA | B7: 0 | C7: 0 | D7: 0 | E7: =SUM(B7+C7)*D7 -> 0
A8: CALDO DE GALINHA | B8: 0 | C8: 0 | D8: 0 | E8: =SUM(B8+C8)*D8 -> 0
A9: CALDO DE FEIJÃO | B9: 0 | C9: 0 | D9: 2.42 | E9: =SUM(B9+C9)*D9 -> 0
A10: CALDO DE MOCOTÓ 250GR | B10: 0 | C10: 0 | D10: 2.99 | E10: =SUM(B10+C10)*D10 -> 0
A11: CALDO DE MOELA | B11: 0 | C11: 0 | D11: 3 | E11: =SUM(B11+C11)*D11 -> 0
A12: CALDO DE RABADA | B12: 0 | C12: 0 | D12: 0 | E12: =SUM(B12+C12)*D12 -> 0
A13: CALDO PERNIL | B13: 0 | C13: 0 | D13: 3 | E13: =SUM(B13+C13)*D13 -> 0
A14: CREME DE AIPIM(0,259G) | B14: 0 | C14: 0.69 | D14: 11 | E14: =SUM(B14+C14)*D14 -> 7.59
... A29: VINAGRETE | B29: 0 | C29: 0 | D29: 8.23 | E29: =SUM(B29+C29)*D29 -> 0
A30: TOTAL | E30: =SUM(E3:E29) -> 443.9293

Sheet Bebidas Álcoolicas
A1: CONTROLE DE ESTOQUE BEBIDAS BAR DO ZECA | L1: BEBIDAS PEDRO PACHECO
A2: BEBIDAS ALCOOLICAS | B2: ESTOQUE | C2: MEDIDA | D2: VALOR (R$) | E2: TOTAL (R$) | F2: PEDIDO | G2: VALOR DO PEDIDO | L2: AZUMA | O2: 0
A3: ANGOSTURA CARIBBEAN RUM | B3: 0 | C3: UND | D3: 152.9 | E3: =B3*D3 -> 0 | F3: 0 | G3: =B3*D3 -> 0 | L3: CAPEL | O3: 0
A4: APERITIVO FERNET AMARGO ASTECA (900ml) | B4: 0 | C4: UND | D4: 97.9 | E4: =B4*D4 -> 0 | F4: 0 | G4: =B4*D4 -> 0 | L4: NOILY PRAT | O4: 0
A5: APERITIVO FERNET BRANCA (750ml) | B5: 0 | C5: UND | D5: 89 | E5: =B5*D5 -> 0 | F5: 0 | G5: =B5*D5 -> 0 | L5: FERNET | O5: 0
A6: APERITIVO JAGERMEISTER (700ml) | B6: 0.9 | C6: UND | D6: 98 | E6: =B6*D6 -> 88.2 | F6: 0 | G6: =B6*D6 -> 88.2 | L6: PARA TUDO | O6: 0
A7: CINZANO V. ROSSO | B7: 0.8 | C7: UND | D7: 26.81 | E7: =B7*D7 -> 21.448 | F7: 0 | G7: =B7*D7 -> 21.448 | L7: YAGUARA | O7: 0
A8: APERITIVO APEROL (750ml) | B8: 20.8 | C8: UND | D8: 43.93 | E8: =B8*D8 -> 913.744 | F8: 0 | G8: =B8*D8 -> 913.744 | L8: SMIRNOFF FRUTADA | O8: 0
A9: APERITIVO CYNAR (900ml) | B9: 1.9 | C9: UND | D9: 17.35 | E9: =B9*D9 -> 32.965 | F9: 0 | G9: =B9*D9 -> 32.965 | L9: KETEL ONE BOTANICAL | O9: 0
A10: APERITIVO CAMPARI MILANO BITTER (900ml) | B10: 22.9 | C10: UND | D10: 47 | E10: =B10*D10 -> 1076.3 | F10: 0 | G10: =B10*D10 -> 1076.3 | L10: ABSOLUT ELIK | O10: 0
A11: APERITIVO PARATUDO (900ml) | B11: 0 | C11: UND | D11: 16 | E11: =B11*D11 -> 0 | F11: 0 | G11: =B11*D11 -> 0 | O11: 0
A12: APERITIVO UNDERBERG | B12: 0 | C12: UND | D12: 43.92 | E12: =B12*D12 -> 0 | F12: 0 | G12: =B12*D12 -> 0
A13: BITTER ANGOSTURA | B13: 0 | C13: UND | D13: 152.9 | E13: =B13*D13 -> 0 | F13: 0 | G13: =B13*D13 -> 0
A14: CACHAÇA 51 | B14: 0 | C14: UND | D14: 7.9067 | E14: =B14*D14 -> 0 | F14: 0 | G14: =B14*D14 -> 0
A15: CACHAÇA GABRIELA | B15: 9.5 | C15: UND | D15: 49.2 | E15: =B15*D15 -> 467.4 | F15: 0 | G15: =B15*D15 -> 467.4
A16: CACHAÇA BANANINHA | B16: 0.5 | C16: UND | D16: 39.9 | E16: =B16*D16 -> 19.95 | F16: 0 | G16: =B16*D16 -> 19.95
A17: CACHAÇA BOAZINHA (600ml) | B17: 0 | C17: UND | D17: 26.26 | E17: =B17*D17 -> 0 | F17: 0 | G17: =B17*D17 -> 0
A18: CACHAÇA COQUEIRO BANANA | B18: 0 | C18: UND | D18: 32 | E18: =B18*D18 -> 0 | F18: 0 | G18: =B18*D18 -> 0
A19: CACHAÇA CRIOULA (600ml) | B19: 0 | C19: UND | D19: 68.49 | E19: =B19*D19 -> 0 | F19: 0 | G19: =B19*D19 -> 0
A20: CACHAÇA DO ZECA | B20: 0 | C20: UND | D20: 17.6 | E20: =B20*D20 -> 0 | F20: 0 | G20: =B20*D20 -> 0
A21: CACHAÇA JAMBUZADA ABACAXI | B21: 0 | C21: UND | D21: 54.9 | E21: =B21*D21 -> 0 | F21: 0 | G21: =B21*D21 -> 0
A22: CACHAÇA JAMBUZADA JAMBU | B22: 0.5 | C22: UND | D22: 54.9 | E22: =B22*D22 -> 27.45 | F22: 0 | G22: =B22*D22 -> 27.45
A23: CACHAÇA JAMBUZADA BANANA | B23: 1 | C23: UND | D23: 54.9 | E23: =B23*D23 -> 54.9 | F23: 0 | G23: =B23*D23 -> 54.9
A24: CACHAÇA JAMBUZADA AÇAI | B24: 4 | C24: UND | D24: 54.9 | E24: =B24*D24 -> 219.6
A25: CACHAÇA JAMBUZADA PRATEADA | B25: 17 | C25: UND | D25: 54.9 | E25: =B25*D25 -> 933.3 | F25: 0 | G25: =B25*D25 -> 933.3
A26: CACHAÇA LEBLON SIGNATURE (375ml) | B26: 0 | C26: UND | D26: 41.1033 | E26: =B26*D26 -> 0 | F26: 0 | G26: =B26*D26 -> 0
A27: CACHAÇA LEBLON (750ml) | B27: 0 | C27: UND | D27: 46.15 | E27: =B27*D27 -> 0 | F27: 0 | G27: =B27*D27 -> 0
A28: CACHAÇA MARIBONDO (890ml) | B28: 0 | C28: UND | D28: 38.48 | E28: =B28*D28 -> 0 | F28: 0 | G28: =B28*D28 -> 0
A29: CACHAÇA MAGNIFICA PRATA | B29: 0 | C29: UND | D29: 36.22 | E29: =B29*D29 -> 0 | F29: 0 | G29: =B29*D29 -> 0
A30: CACHAÇA MAGNIFICA EXTRA PREMIUM | B30: 0 | C30: UND | D30: 94.4 | E30: =B30*D30 -> 0 | F30: 0 | G30: =B30*D30 -> 0
A31: CACHAÇA NEGA FULÔ CARVALHO (750ml) | B31: 0 | C31: UND | D31: 65.88 | E31: =B31*D31 -> 0 | F31: 0 | G31: =B31*D31 -> 0
A32: CACHAÇA SANTO GRAU PARATY (750ml) | B32: 0 | C32: UND | D32: 62.61 | E32: =B32*D32 -> 0 | F32: 0 | G32: =B32*D32 -> 0
A33: CACHAÇA SALINAS TRADICIONAL (600ml) | B33: 1.7 | C33: UND | D33: 34.99 | E33: =B33*D33 -> 59.483 | F33: 0 | G33: =B33*D33 -> 59.483
A34: CACHAÇA SAGATIBA PURA (700ml) | B34: 81 | C34: UND | D34: 25 | E34: =B34*D34 -> 2025 | F34: 0 | G34: =B34*D34 -> 2025
A35: CACHAÇA SELETA (600ml) | B35: 0 | C35: UND | D35: 31.61 | E35: =B35*D35 -> 0 | F35: 0 | G35: =B35*D35 -> 0
A36: CACHAÇA SOLEDADE 5 MADEIRAS | B36: 0 | C36: UND | D36: 81.9 | E36: =B36*D36 -> 0 | F36: 0 | G36: =B36*D36 -> 0
... A48: CERVEJA ANTARCTICA ORIGINAL (600ml) | B48: 545 | C48: UND | D48: 6.68 | E48: =B48*D48 -> 3640.6 | F48: 0 | G48: =B48*D48 -> 3640.6
A49: CERVEJA BRAHMA (600ml) | B49: 438 | C49: UND | D49: 6.36 | E49: =B49*D49 -> 2785.68
A50: CERVEJA BRAHMA DUPLO MALTE (330ml) | B50: 0 | C50: UND | D50: 3.29 | E50: =B50*D50 -> 0 | F50: 0 | G50: =B50*D50 -> 0
A51: CILINDROS | B51: 3 | C51: UND | D51: 122.75 | E51: =B51*D51 -> 368.25 | F51: 0 | G51: =B51*D51 -> 368.25
...

Sheet Bebidas não Álcoolicas
A1: BEBIDAS NÃO ALCOÓLICAS (ESTOQUE) | B1: ESTOQUE | C1: MEDIDA | D1: VALOR (R$) | E1: TOTAL (R$) | F1: PEDIDO | G1: VALOR DO PEDIDO
A2: ÁGUA SEM GÁS (1,5lts) | B2: 0 | C2: UND | D2: 3 | E2: =B2*D2 -> 0 | F2: 0 | G2: =D2*F2 -> 0
A3: ÁGUA COM GÁS 1,5 LT | B3: 0 | C3: UND | D3: 3 | E3: =B3*D3 -> 0 | F3: 0 | G3: =D3*F3 -> 0
A4: ÁGUA SEM GÁS (350ml) | B4: 235 | C4: UND | D4: 1.19 | E4: =B4*D4 -> 279.65 | F4: 0 | G4: =D4*F4 -> 0
A5: ÁGUA COM GÁS (350ml) | B5: 132 | C5: UND | D5: 1.19 | E5: =B5*D5 -> 157.08 | F5: 0 | G5: =D5*F5 -> 0
A6: ÁGUA DE COCO (200ml) | B6: 6 | C6: UND | D6: 2.08 | E6: =B6*D6 -> 12.48 | F6: 0 | G6: =D6*F6 -> 0
A7: ÁGUA DE COCO (1lts) | B7: 0 | C7: UND | D7: 7.68 | E7: =B7*D7 -> 0 | F7: 0 | G7: =D7*F7 -> 0
A8: COCA COLA 2LTS | B8: 0 | C8: UND | D8: 9.83 | E8: =B8*D8 -> 0 | F8: 0 | G8: =D8*F8 -> 0
A9: COCA COLA ZERO 2LTS | B9: 0 | C9: UND | D9: 9.83 | E9: =B9*D9 -> 0 | F9: 0 | G9: =D9*F9 -> 0
A10: COCA COLA KS | B10: 227 | C10: UND | D10: 2.25 | E10: =B10*D10 -> 510.75 | F10: 0 | G10: =D10*F10 -> 0
A11: COCA COLA ZERO KS | B11: 212 | C11: UND | D11: 2.25 | E11: =B11*D11 -> 477 | F11: 0 | G11: =D11*F11 -> 0
A12: COCA COLA LATA | B12: 0 | C12: UND | D12: 3.26 | E12: =B12*D12 -> 0 | F12: 0 | G12: =D12*F12 -> 0
A13: COCA COLA ZERO LATA | B13: 0 | C13: UND | D13: 3.26 | E13: =B13*D13 -> 0 | F13: 0 | G13: =D13*F13 -> 0
... A64: XAROPE MONIN MIJOTO | B64: 0 | C64: UND | D64: 67.86 | E64: =B64*D64 -> 0 | F64: 0 | G64: =D64*F64 -> 0
A65: XAROPE MONIN RASPBERRY | B65: 0 | C65: UND | D65: 67.86 | E65: =B65*D65 -> 0
A66: XAROPE MONIN ROMÃ | B66: 0 | C66: UND | D66: 67.86 | E66: =B66*D66 -> 0 | F66: 0 | G66: =D66*F66 -> 0
A67: XAROPE MONIN PIPOCA | B67: 0 | C67: UND | D67: 67.86 | E67: =B67*D67 -> 0 | F67: 0 | G67: =D67*F67 -> 0
A68: XAROPE MONIN SPICY MANGO (700ml) | B68: 1 | C68: UND | D68: 67.86 | E68: =B68*D68 -> 67.86 | F68: 0 | G68: =D68*F68 -> 0
A69: XAROPE MONIN CARAMEL BOTTEGA | B69: 0 | C69: UND | D69: 67.86 | E69: =B69*D69 -> 0 | F69: 0 | G69: =D69*F69 -> 0
A70: XAROPE MONIN VIOLETA (700ml) | B70: 0 | C70: UND | D70: 67.86 | E70: =B70*D70 -> 0 | F70: 0 | G70: =D70*F70 -> 0
A72: TOTAL BEBIDAS NÃO ALCOÓLICAS | E72: =SUM(E2:E70) -> 7234.546 | G72: =SUM(G17:G70) -> 0

Sheet Perda
A1: PERDAS
A2: Produto | B2: Quantidade | C2: Valor Unitario/kg | D2: Valor Total
B3: 0 | C3: 0 | D3: =B3*C3 -> 0
