Workbook

Sheet EMPADÃO DE FRANGO COM SALADA 
A1: Categoria | C1: Executivo | G1: Custo total | I1: =I12 -> 5.4251223 | J1: =J12 -> 7.0184
A2: Preparação | C2: EMPADÃO DE FRANGO COM SALADA | G2: Custo porção | I2: =I1/C4 -> 5.4251223 | J2: =J1/C4 -> 7.0184
A3: Rendimento (porções) | C3: =E12/C4 -> 0.64 | G3: Índice de custo | I3: 5 | J3: 5
A4: Peso Porção | C4: 1 | G4: Preço de venda | I4: =I2*I3 -> 27.125612 | J4: =J2*J3 -> 35.092
A5: Obs: | C5: Executivo Bar do Zeca | G5: CMV | I5: =I2/I4 -> 0.2 | J5: =J2/J4 -> 0.2
A7: Ingrediente | B7: Código SKU | C7: PesoBruto | D7: Perda manipulação | E7: Peso Líquido | F7: Unidade | G7: Fator de Correção | H7: Custo compra | I7: Valor produção | J7: Valor preço de custo
A8: empadão de frango | C8: 0.18 | D8: 0 | E8: 0.18 | F8: KG | G8: =C8/E8 -> 1 | H8: =I52 -> 11.610124 | I8: =E8*H8 -> 2.0898223 | J8: =C8*12.64 -> 2.2752
A9: salada da casa( individual) | C9: 0.14 | D9: 0 | E9: 0.14 | F9: porção | G9: =C9/E9 -> 1 | H9: =I67 -> 18.295 | I9: =E9*H9 -> 2.5613 | J9: =J78 -> 3.9692
A10: arroz branco pronto | C10: 0.2 | D10: 0 | E10: 0.2 | F10: KG | G10: =C10/E10 -> 1 | H10: 1.98 | I10: =E10*H10 -> 0.396 | J10: =C10*H10 -> 0.396
A11: feijãp preto pronto | C11: 0.12 | D11: 0 | E11: 0.12 | F11: KG | G11: =C11/E11 -> 1 | H11: 3.15 | I11: =E11*H11 -> 0.378 | J11: =C11*H11 -> 0.378
A12: TOTAL | C12: =SUM(C8:C11) -> 0.64 | E12: =SUM(E8:E11) -> 0.64 | F12: KG | H12: VALOR TOTAL | I12: =SUM(I8:I11) -> 5.4251223 | J12: =SUM(J8:J11) -> 7.0184
C13: 0.02 | D13: 0 | E13: 0.02 | F13: L | G13: =C13/E13 -> 1 | I13: =E13*H13 -> 0
C14: =SUM(C8:C13) -> 1.3 | D14: 0 | E14: =SUM(E8:E13) -> 1.3 | F14: KG | G14: =C14/E14 -> 1 | H14: VALOR TOTAL | I14: =SUM(I8:I13) -> 10.850245
A17: Categoria | C17: Executivo | G17: Custo total | I17: =I28 -> 8.0144 | J17: =J28 -> 8.0144
A18: Preparação | C18: MASSA EMPADÃO | G18: Custo porção | I18: =I17/C20 -> 4.8572121 | J18: =J17/C20 -> 4.8572121
A19: Rendimento (porções) | C19: =E28/C20 -> 1 | G19: Índice de custo | I19: 5 | J19: 5
A20: Peso Porção | C20: =E28 -> 1.65 | G20: Preço de venda | I20: =I18*I19 -> 24.286061 | J20: =J18*J19 -> 24.286061
A21: Obs: | C21: Executivo Bar do Zeca | G21: CMV | I21: =I18/I20 -> 0.2 | J21: =J18/J20 -> 0.2
A23: Ingrediente | B23: Código SKU | C23: PesoBruto | D23: Perda manipulação | E23: Peso Líquido | F23: Unidade | G23: Fator de Correção | H23: Custo compra | I23: Valor produção | J23: Valor preço de custo
A24: farinha de trigo | C24: 1 | D24: 0 | E24: 1 | F24: KG | G24: =C24/E24 -> 1 | H24: 5.9 | I24: =E24*H24 -> 5.9 | J24: =C24*H24 -> 5.9
A25: banha | C25: 0.5 | D25: 0 | E25: 0.5 | F25: KG | G25: =C25/E25 -> 1 | H25: 1 | I25: =E25*H25 -> 0.5 | J25: =C25*H25 -> 0.5
A26: ovo | C26: 3 | D26: 0 | E26: 3 | F26: und | G26: =C26/E26 -> 1 | H26: 0.52 | I26: =E26*H26 -> 1.56 | J26: =C26*H26 -> 1.56
A27: sal | C27: 0.02 | D27: 0 | E27: 0.02 | F27: KG | H27: 2.72 | I27: =E27*H27 -> 0.0544 | J27: =C27*H27 -> 0.0544
A28: TOTAL | C28: 1.65 | E28: 1.65 | F28: KG | H28: VALOR TOTAL | I28: =SUM(I24:I27) -> 8.0144 | J28: =SUM(J24:J27) -> 8.0144
C29: 0.02 | D29: 0 | E29: 0.02 | F29: L | G29: =C29/E29 -> 1 | I29: =E29*H29 -> 0
A31: Categoria | C31: Executivo | G31: Custo total | I31: =I47 -> 33.3285 | J31: =J47 -> 36.7065
A32: Preparação | C32: RECHEIO EMPADÃO | G32: Custo porção | I32: =I31/C34 -> 13.743711 | J32: =J31/C34 -> 15.136701
A33: Rendimento (porções) | C33: =E47/C34 -> 1 | G33: Índice de custo | I33: 5 | J33: 5
A34: Peso Porção | C34: =E47 -> 2.425 | G34: Preço de venda | I34: =I32*I33 -> 68.718557 | J34: =J32*J33 -> 75.683505
A35: Obs: | C35: Executivo Bar do Zeca | G35: CMV | I35: =I32/I34 -> 0.2 | J35: =J32/J34 -> 0.2
A37: Ingrediente | B37: Código SKU | C37: PesoBruto | D37: Perda manipulação | E37: Peso Líquido | F37: Unidade | G37: Fator de Correção | H37: Custo compra | I37: Valor produção | J37: Valor preço de custo
A38: filé de frango | C38: 1.5 | D38: 0.1 | E38: 1.4 | F38: KG | G38: =C38/E38 -> 1.0714286 | H38: 14.44 | I38: =E38*H38 -> 20.216 | J38: =C38*H38 -> 21.66
A39: cebola branca | C39: 0.3 | D39: 0.05 | E39: 0.25 | F39: KG | G39: =C39/E39 -> 1.2 | H39: 8.7 | I39: =E39*H39 -> 2.175 | J39: =C39*H39 -> 2.61
A40: tomate | C40: 0.4 | D40: 0.1 | E40: 0.3 | F40: KG | G40: =C40/E40 -> 1.3333333 | H40: 14.99 | I40: =E40*H40 -> 4.497 | J40: =C40*H40 -> 5.996
A41: alho batido | C41: 0.05 | D41: 0 | E41: 0.05 | F41: KG | G41: =C41/E41 -> 1 | H41: 20.5 | I41: =E41*H41 -> 1.025 | J41: =C41*H41 -> 1.025
A42: ervilha congelada | C42: 0.2 | D42: 0 | E42: 0.2 | F42: KG | G42: =C42/E42 -> 1 | H42: 12.88 | I42: =E42*H42 -> 2.576 | J42: =C42*H42 -> 2.576
A43: extrato de tomate | C43: 0.1 | D43: 0 | E43: 0.1 | F43: KG | G43: =C43/E43 -> 1 | H43: 14.38 | I43: =E43*H43 -> 1.438 | J43: =C43*H43 -> 1.438
A44: salsa picada | C44: 0.05 | D44: 0 | E44: 0.05 | F44: KG | G44: =C44/E44 -> 1 | H44: 25.67 | I44: =E44*H44 -> 1.2835 | J44: =C44*H44 -> 1.2835
A45: banha | C45: 0.05 | D45: 0 | E45: 0.05 | F45: KG | G45: =C45/E45 -> 1 | H45: 1 | I45: =E45*H45 -> 0.05 | J45: =C45*H45 -> 0.05
A46: sal com pimenta | C46: 0.025 | D46: 0 | E46: 0.025 | F46: KG | G46: =C46/E46 -> 1 | H46: 2.72 | I46: =E46*H46 -> 0.068 | J46: =C46*H46 -> 0.068
...

Sheet MINI ORELHA EXECUTIVO
A1: Categoria | C1: Executivo | G1: Custo total | I1: =I17 -> 9.1661 | J1: =J17 -> 9.9136
A2: Preparação | C2: MINI ORELHA DE ELEFANTE | G2: Custo porção | I2: =I1/C4 -> 9.1661 | J2: =J1/C4 -> 9.9136
A3: Rendimento (porções) | C3: =E17/C4 -> 0.585 | G3: Índice de custo | I3: 5 | J3: 5
A4: Peso Porção | C4: 1 | G4: Preço de venda | I4: =I2*I3 -> 45.8305 | J4: =J2*J3 -> 49.568
A5: Obs: | C5: Executivo Bar do Zeca | G5: CMV | I5: =I2/I4 -> 0.2 | J5: =J2/J4 -> 0.2
A7: Ingrediente | B7: Código SKU | C7: PesoBruto | D7: Perda manipulação | E7: Peso Líquido | F7: Unidade | G7: Fator de Correção | H7: Custo compra | I7: Valor produção | J7: Valor preço de custo
A8: bombom de alcatra | C8: 0.1 | D8: 0 | E8: 0.09 | F8: KG | G8: =C8/E8 -> 1.1111111 | H8: 69.75 | I8: =E8*H8 -> 6.2775 | J8: =C8*H8 -> 6.975
A9: arroz branco pronto | C9: 0.2 | D9: 0 | E9: 0.2 | F9: KG | G9: =C9/E9 -> 1 | H9: 1.98 | I9: =E9*H9 -> 0.396 | J9: =C9*H9 -> 0.396
A10: guarnição à francesa | C10: 0.1 | D10: 0 | E10: 0.1 | F10: KG | G10: =C10/E10 -> 1 | H10: 11.63 | I10: =E10*H10 -> 1.163 | J10: =C10*12.13 -> 1.213
A11: feijão pronto | C11: 0.12 | D11: 0 | E11: 0.12 | F11: KG | G11: =C11/E11 -> 1 | H11: 3.15 | I11: =E11*H11 -> 0.378 | J11: =C11*H11 -> 0.378
A12: alho batido | C12: 0.02 | D12: 0 | E12: 0.02 | F12: KG | G12: =C12/E12 -> 1 | H12: 20.5 | I12: =E12*H12 -> 0.41 | J12: =C12*H12 -> 0.41
A13: sal com pimenta | C13: 0.005 | D13: 0 | E13: 0.005 | F13: KG | G13: =C13/E13 -> 1 | H13: 2.72 | I13: =E13*H13 -> 0.0136 | J13: =C13*H13 -> 0.0136
A14: leitiosa de empanamento | C14: 0.02 | D14: 0 | E14: 0.02 | F14: kg | G14: =C14/E14 -> 1 | H14: 7.25 | I14: =E14*H14 -> 0.145 | J14: =C14*H14 -> 0.145
A15: farinha pankp | C15: 0.02 | D15: 0 | E15: 0.02 | F15: kg | G15: =C15/E15 -> 1 | H15: 16.2 | I15: =E15*H15 -> 0.324 | J15: =C15*H15 -> 0.324
A16: farinha de trigo | C16: 0.01 | D16: 0 | E16: 0.01 | F16: L | G16: =C16/E16 -> 1 | H16: 5.9 | I16: =E16*H16 -> 0.059 | J16: =C16*H16 -> 0.059
A17: TOTAL | C17: =SUM(C8:C16) -> 0.595 | E17: =SUM(E8:E16) -> 0.585 | F17: KG | H17: VALOR TOTAL | I17: =SUM(I8:I16) -> 9.1661 | J17: =SUM(J8:J16) -> 9.9136
C18: 0.02 | D18: 0 | E18: 0.02 | F18: L | G18: =C18/E18 -> 1 | I18: =E18*H18 -> 0
A21: Categoria | C21: Executivo | G21: Custo total | I21: =I34 -> 2.03595 | J21: =J34 -> 2.12295
A22: Preparação | C22: GUARNIÇÃO A FRANCESA | G22: Custo porção | I22: =I21/C24 -> 11.634 | J22: =J21/C24 -> 12.131143
A23: Rendimento (porções) | C23: 1 | G23: Índice de custo | I23: 5 | J23: 5
A24: Peso Porção | C24: =E34/C23 -> 0.175 | G24: Preço de venda | I24: =I22*I23 -> 58.17 | J24: =J22*J23 -> 60.655714
A25: Obs: | C25: Executivo Bar do Zeca | G25: CMV | I25: =I22/I24 -> 0.2 | J25: =J22/J24 -> 0.2
A27: Ingrediente | B27: Código SKU | C27: PesoBruto | D27: Perda manipulação | E27: Peso Líquido | F27: Unidade | G27: Fator de Correção | H27: Custo compra | I27: Valor produção | J27: Valor preço de custo
A28: Batata palha MP | C28: 0.08 | D28: 0 | E28: 0.08 | F28: KG | G28: =C28/E28 -> 1 | H28: 8.62 | I28: =E28*H28 -> 0.6896 | J28: =C28*H28 -> 0.6896
A29: Presunto | C29: 0.03 | D29: 0 | E29: 0.03 | F29: KG | G29: =C29/E29 -> 1 | H29: 22.98 | I29: =E29*H29 -> 0.6894 | J29: =C29*H29 -> 0.6894
A30: Cebola branca | C30: 0.04 | D30: 0 | E30: 0.03 | F30: KG | G30: =C30/E30 -> 1.3333333 | H30: 8.7 | I30: =E30*H30 -> 0.261 | J30: =C30*H30 -> 0.348
A31: Ervilha congelada | C31: 0.02 | D31: 0 | E31: 0.02 | F31: KG | G31: =C31/E31 -> 1 | H31: 12.88 | I31: =E31*H31 -> 0.2576 | J31: =C31*H31 -> 0.2576
A32: Salsa picada | C32: 0.005 | D32: 0 | E32: 0.005 | F32: KG | G32: =C32/E32 -> 1 | H32: 25.67 | I32: =E32*H32 -> 0.12835 | J32: =C32*H32 -> 0.12835
A33: Banha | C33: 0.01 | D33: 0 | E33: 0.01 | F33: KG | G33: =C33/E33 -> 1 | H33: 1 | I33: =E33*H33 -> 0.01 | J33: =C33*H33 -> 0.01
A34: TOTAL | C34: =SUM(C28:C33) -> 0.185 | E34: =SUM(E28:E33) -> 0.175 | F34: KG | H34: VALOR TOTAL | I34: =SUM(I28:I33) -> 2.03595 | J34: =SUM(J28:J33) -> 2.12295
C35: 0.02 | D35: 0 | E35: 0.02 | F35: L | G35: =C35/E35 -> 1 | I35: =E35*H35 -> 0

Sheet CARNE GUISADA  COM BATATA CORAD
A1: Categoria | C1: Executivo | G1: Custo total | I1: =I14 -> 8.2061 | J1: =J14 -> 8.9211
A2: Preparação | C2: CARNE GUISADA COM BATATA CORADA | G2: Custo porção | I2: =I1/C4 -> 8.2061 | J2: =J1/C4 -> 8.9211
A3: Rendimento (porções) | C3: =E14/C4 -> 0.575 | G3: Índice de custo | I3: 5 | J3: 5
A4: Peso Porção | C4: 1 | G4: Preço de venda | I4: =I2*I3 -> 41.0305 | J4: =J2*J3 -> 44.6055
A5: Obs: | C5: Executivo Bar do Zeca | G5: CMV | I5: =I2/I4 -> 0.2 | J5: =J2/J4 -> 0.2
A7: Ingrediente | B7: Código SKU | C7: PesoBruto | D7: Perda manipulação | E7: Peso Líquido | F7: Unidade | G7: Fator de Correção | H7: Custo compra | I7: Valor produção | J7: Valor preço de custo
A8: acém mp | C8: 0.1 | D8: 0 | E8: 0.1 | F8: KG | G8: =C8/E8 -> 1 | H8: 62.6 | I8: =E8*H8 -> 6.26 | J8: =C8*H8 -> 6.26
A9: arroz branco pronto | C9: 0.2 | D9: 0 | E9: 0.2 | F9: KG | G9: =C9/E9 -> 1 | H9: 1.98 | I9: =E9*H9 -> 0.396 | J9: =C9*H9 -> 0.396
A10: batata asterix | C10: 0.2 | D10: 0 | E10: 0.1 | F10: KG | G10: =C10/E10 -> 2 | H10: 7.15 | I10: =E10*H10 -> 0.715 | J10: =C10*H10 -> 1.43
A11: feijão pronto | C11: 0.12 | D11: 0 | E11: 0.12 | F11: KG | G11: =C11/E11 -> 1 | H11: 3.15 | I11: =E11*H11 -> 0.378 | J11: =C11*H11 -> 0.378
A12: farofa de bacon | C12: 0.05 | D12: 0 | E12: 0.05 | F12: KG | G12: =C12/E12 -> 1 | H12: 8.87 | I12: =E12*H12 -> 0.4435 | J12: =C12*H12 -> 0.4435
A13: sal com pimenta | C13: 0.005 | D13: 0 | E13: 0.005 | F13: KG | G13: =C13/E13 -> 1 | H13: 2.72 | I13: =E13*H13 -> 0.0136 | J13: =C13*H13 -> 0.0136
A14: TOTAL | C14: =SUM(C8:C13) -> 0.675 | E14: =SUM(E8:E13) -> 0.575 | F14: KG | H14: VALOR TOTAL | I14: =SUM(I8:I13) -> 8.2061 | J14: =SUM(J8:J13) -> 8.9211
C15: 0.02 | D15: 0 | E15: 0.02 | F15: L | G15: =C15/E15 -> 1 | I15: =E15*H15 -> 0
C16: =SUM(C8:C15) -> 1.37 | D16: 0 | E16: =SUM(E8:E15) -> 1.17 | F16: KG | G16: =C16/E16 -> 1.1709402 | H16: VALOR TOTAL | I16: =SUM(I8:I15) -> 16.4122

Sheet CARNE SECA COM TUTU À MINEIRA
A1: Categoria | C1: Executivo | G1: Custo total | I1: =I19 -> 9.0976274 | J1: =J19 -> 17.133727
A2: Preparação | C2: CARNE SECA COM TUTU A MINEIRA | G2: Custo porção | I2: =I1/C4 -> 9.0976274 | J2: =J1/C4 -> 17.133727
A3: Rendimento (porções) | C3: =E19/C4 -> 0.68 | G3: Índice de custo | I3: 5 | J3: 5
A4: Peso Porção | C4: 1 | G4: Preço de venda | I4: =I2*I3 -> 45.488137 | J4: =J2*J3 -> 85.668637
A5: Obs: | C5: Executivo Bar do Zeca | G5: CMV | I5: =I2/I4 -> 0.2 | J5: =J2/J4 -> 0.2
A7: Ingrediente | B7: Código SKU | C7: PesoBruto | D7: Perda manipulação | E7: Peso Líquido | F7: Unidade | G7: Fator de Correção | H7: Custo compra | I7: Valor produção | J7: Valor preço de custo
A8: carne seca desfiada | C8: 0.16 | D8: 0.08 | E8: 0.08 | F8: KG | G8: =C8/E8 -> 2 | H8: 49.22 | I8: =E8*H8 -> 3.9376 | J8: =C8*H8 -> 7.8752
A9: cebola branca | C9: 0.07 | D9: 0.02 | E9: 0.05 | F9: KG | G9: =C9/E9 -> 1.4 | H9: 8.7 | I9: =E9*H9 -> 0.435 | J9: =C9*H9 -> 0.609
A10: tomate picado | C10: 0.2 | D10: 0.15 | E10: 0.05 | F10: KG | G10: =C10/E10 -> 4 | H10: 14.99 | I10: =E10*H10 -> 0.7495 | J10: =C10*H10 -> 2.998
A11: salsa picada | C11: 0.015 | D11: 0 | E11: 0.015 | F11: KG | G11: =C11/E11 -> 1 | H11: 25.67 | I11: =E11*H11 -> 0.38505 | J11: =C11*H11 -> 0.38505
A12: banha | C12: 0.04 | D12: 0 | E12: 0.04 | F12: KG | G12: =C12/E12 -> 1 | H12: 1 | I12: =E12*H12 -> 0.04 | J12: =C12*H12 -> 0.04
A13: arroz branco pronto | C13: 0.2 | D13: 0 | E13: 0.2 | F13: KG | G13: =C13/E13 -> 1 | H13: 1.98 | I13: =E13*H13 -> 0.396 | J13: =C13*H13 -> 0.396
A14: couve refogada mp | C14: 0.1 | D14: 0 | E14: 0.05 | F14: KG | G14: =C14/E14 -> 2 | H14: 33.52 | I14: =E14*H14 -> 1.676 | J14: =C14*H14 -> 3.352
A15: tutu de feijão mp | C15: 0.12 | D15: 0 | E15: 0.12 | F15: KG | G15: =C15/E15 -> 1 | H15: =I25 -> 5.094812 | I15: =E15*H15 -> 0.61137744 | J15: =C15*H15 -> 0.61137744
A16: farofa de bacon | C16: 0.05 | D16: 0 | E16: 0.05 | F16: KG | G16: =C16/E16 -> 1 | H16: 8.87 | I16: =E16*H16 -> 0.4435 | J16: =C16*H16 -> 0.4435
A17: sal com pimenta | C17: 0.005 | D17: 0 | E17: 0.005 | F17: KG | G17: =C17/E17 -> 1 | H17: 2.72 | I17: =E17*H17 -> 0.0136 | J17: =C17*H17 -> 0.0136
A18: alho batido | C18: 0.02 | D18: 0 | E18: 0.02 | F18: KG | G18: =C18/E18 -> 1 | H18: 20.5 | I18: =E18*H18 -> 0.41 | J18: =C18*H18 -> 0.41
A19: TOTAL | C19: =SUM(C8:C18) -> 0.98 | E19: =SUM(E8:E18) -> 0.68 | F19: KG | H19: VALOR TOTAL | I19: =SUM(I8:I18) -> 9.0976274 | J19: =SUM(J8:J18) -> 17.133727
C20: 0.02 | D20: 0 | E20: 0.02 | F20: L | G20: =C20/E20 -> 1 | I20: =E20*H20 -> 0
C21: =SUM(C8:C20) -> 1.98 | D21: 0 | E21: =SUM(E8:E20) -> 1.38 | F21: KG | G21: =C21/E21 -> 1.4347826 | H21: VALOR TOTAL | I21: =SUM(I8:I20) -> 18.195255
A24: Categoria | C24: Executivo | G24: Custo total | I24: =I38 -> 6.7761 | J24: =J38 -> 6.7761
A25: Preparação | C25: TUTU DE FEIJÃO PRETO | G25: Custo porção | I25: =I24/C27 -> 5.094812 | J25: =J24/C27 -> 5.094812
A26: Rendimento (porções) | C26: =E38/C27 -> 1 | G26: Índice de custo | I26: 5 | J26: 5
A27: Peso Porção | C27: =E38 -> 1.33 | G27: Preço de venda | I27: =I25*I26 -> 25.47406 | J27: =J25*J26 -> 25.47406
A28: Obs: | C28: Executivo Bar do Zeca | G28: CMV | I28: =I25/I27 -> 0.2 | J28: =J25/J27 -> 0.2
A30: Ingrediente | B30: Código SKU | C30: PesoBruto | D30: Perda manipulação | E30: Peso Líquido | F30: Unidade | G30: Fator de Correção | H30: Custo compra | I30: Valor produção | J30: Valor preço de custo
A31: Feijão preto pronto | C31: 1 | D31: 0 | E31: 1 | F31: KG | G31: =C31/E31 -> 1 | H31: 3.15 | I31: =E31*H31 -> 3.15 | J31: =C31*H31 -> 3.15
A32: farinha de mandioca | C32: 0.15 | D32: 0 | E32: 0.15 | F32: KG | G32: =C32/E32 -> 1 | H32: 5.37 | I32: =E32*H32 -> 0.8055 | J32: =C32*H32 -> 0.8055
A33: alho batido | C33: 0.03 | D33: 0 | E33: 0.03 | F33: KG | G33: =C33/E33 -> 1 | H33: 20.5 | I33: =E33*H33 -> 0.615 | J33: =C33*H33 -> 0.615
A34: bacon picado | C34: 0.1 | D34: 0 | E34: 0.1 | F34: KG | H34: 16.45 | I34: =E34*H34 -> 1.645 | J34: =C34*H34 -> 1.645
A35: sal com pimenta | C35: 0.01 | D35: 0 | E35: 0.01 | F35: KG | G35: =C35/E35 -> 1 | H35: 2.72 | I35: =E35*H35 -> 0.0272 | J35: =C35*H35 -> 0.0272
A36: banha | C36: 0.02 | D36: 0 | E36: 0.02 | F36: KG | G36: =C36/E36 -> 1 | H36: 1 | I36: =E36*H36 -> 0.02 | J36: =C36*H36 -> 0.02
A37: salsa picada | C37: 0.02 | D37: 0 | E37: 0.02 | F37: KG | G37: =C37/E37 -> 1 | H37: 25.67 | I37: =E37*H37 -> 0.5134 | J37: =C37*H37 -> 0.5134
A38: TOTAL | C38: =SUM(C31:C37) -> 1.33 | E38: =SUM(E31:E37) -> 1.33 | F38: KG | H38: VALOR TOTAL | I38: =SUM(I31:I37) -> 6.7761 | J38: =SUM(J31:J37) -> 6.7761
C39: 0.02 | D39: 0 | E39: 0.02 | F39: L | G39: =C39/E39 -> 1 | I39: =E39*H39 -> 0

Sheet ISCA DE FÍGADO COM PURÊ
A1: Categoria | C1: Executivo | G1: Custo total | I1: =I17 -> 4.92155 | J1: =J17 -> 5.48615
A2: Preparação | C2: isca de fígado com purê | G2: Custo porção | I2: =I1/C4 -> 4.92155 | J2: =J1/C4 -> 5.48615
A3: Rendimento (porções) | C3: =E17/C4 -> 0.7 | G3: Índice de custo | I3: 5 | J3: 5
A4: Peso Porção | C4: 1 | G4: Preço de venda | I4: =I2*I3 -> 24.60775 | J4: =J2*J3 -> 27.43075
A5: Obs: | C5: Executivo Bar do Zeca | G5: CMV | I5: =I2/I4 -> 0.2 | J5: =J2/J4 -> 0.2
A7: Ingrediente | B7: Código SKU | C7: PesoBruto | D7: Perda manipulação | E7: Peso Líquido | F7: Unidade | G7: Fator de Correção | H7: Custo compra | I7: Valor produção | J7: Valor preço de custo
A8: isca de fígado de boi | C8: 0.15 | D8: 0.02 | E8: 0.12 | F8: KG | G8: =C8/E8 -> 1.25 | H8: 13.02 | I8: =E8*H8 -> 1.5624 | J8: =C8*H8 -> 1.953
A9: purê de batata mp | C9: 0.15 | D9: 0 | E9: 0.15 | F9: KG | G9: =C9/E9 -> 1 | H9: 8.81 | I9: =E9*H9 -> 1.3215 | J9: =C9*H9 -> 1.3215
A10: cebola branca | C10: 0.07 | D10: 0.02 | E10: 0.05 | F10: KG | G10: =C10/E10 -> 1.4 | H10: 8.7 | I10: =E10*H10 -> 0.435 | J10: =C10*H10 -> 0.609
A11: salsa picada | C11: 0.015 | D11: 0 | E11: 0.015 | F11: KG | G11: =C11/E11 -> 1 | H11: 25.67 | I11: =E11*H11 -> 0.38505 | J11: =C11*H11 -> 0.38505
A12: banha | C12: 0.02 | D12: 0 | E12: 0.02 | F12: KG | G12: =C12/E12 -> 1 | H12: 1 | I12: =E12*H12 -> 0.02 | J12: =C12*H12 -> 0.02
A13: arroz branco pronto | C13: 0.2 | D13: 0 | E13: 0.2 | F13: KG | G13: =C13/E13 -> 1 | H13: 1.98 | I13: =E13*H13 -> 0.396 | J13: =C13*H13 -> 0.396
A14: feijão preto mp | C14: 0.12 | D14: 0 | E14: 0.12 | F14: KG | G14: =C14/E14 -> 1 | H14: 3.15 | I14: =E14*H14 -> 0.378 | J14: =C14*H14 -> 0.378
A15: sal com pimenta | C15: 0.005 | D15: 0 | E15: 0.005 | F15: KG | G15: =C15/E15 -> 1 | H15: 2.72 | I15: =E15*H15 -> 0.0136 | J15: =C15*H15 -> 0.0136
A16: alho batido | C16: 0.02 | D16: 0 | E16: 0.02 | F16: KG | G16: =C16/E16 -> 1 | H16: 20.5 | I16: =E16*H16 -> 0.41 | J16: =C16*H16 -> 0.41
A17: TOTAL | C17: =SUM(C8:C16) -> 0.75 | E17: =SUM(E8:E16) -> 0.7 | F17: KG | H17: VALOR TOTAL | I17: =SUM(I8:I16) -> 4.92155 | J17: =SUM(J8:J16) -> 5.48615
C18: 0.02 | D18: 0 | E18: 0.02 | F18: L | G18: =C18/E18 -> 1 | I18: =E18*H18 -> 0
C19: =SUM(C8:C18) -> 1.52 | D19: 0 | E19: =SUM(E8:E18) -> 1.42 | F19: KG | G19: =C19/E19 -> 1.0704225 | H19: VALOR TOTAL | I19: =SUM(I8:I18) -> 9.8431

Sheet FILÉ FRANGO EMPANADO COM FRITAS
A1: Categoria | C1: Executivo | G1: Custo total | I1: =I18 -> 5.4844 | J1: =J18 -> 5.6787
A2: Preparação | C2: FILÉ DE FRANGO COM FRITAS | G2: Custo porção | I2: =I1/C4 -> 5.4844 | J2: =J1/C4 -> 5.6787
A3: Rendimento (porções) | C3: =E18/C4 -> 0.695 | G3: Índice de custo | I3: 5 | J3: 5
A4: Peso Porção | C4: 1 | G4: Preço de venda | I4: =I2*I3 -> 27.422 | J4: =J2*J3 -> 28.3935
A5: Obs: | C5: Executivo Bar do Zeca | G5: CMV | I5: =I2/I4 -> 0.2 | J5: =J2/J4 -> 0.2
A7: Ingrediente | B7: Código SKU | C7: PesoBruto | D7: Perda manipulação | E7: Peso Líquido | F7: Unidade | G7: Fator de Correção | H7: Custo compra | I7: Valor produção | J7: Valor preço de custo
A8: filé de frango | C8: 0.12 | D8: 0 | E8: 0.1 | F8: KG | G8: =C8/E8 -> 1.2 | H8: 14.44 | I8: =E8*H8 -> 1.444 | J8: =C8*H8 -> 1.7328
A9: arroz branco pronto | C9: 0.2 | D9: 0 | E9: 0.2 | F9: KG | G9: =C9/E9 -> 1 | H9: 1.98 | I9: =E9*H9 -> 0.396 | J9: =C9*H9 -> 0.396
A10: batata frita | C10: 0.15 | D10: 0 | E10: 0.15 | F10: KG | G10: =C10/E10 -> 1 | H10: 13.75 | I10: =E10*H10 -> 2.0625 | J10: =C10*H10 -> 2.0625
A11: feijão pronto | C11: 0.12 | D11: 0 | E11: 0.15 | F11: KG | G11: =C11/E11 -> 0.8 | H11: 3.15 | I11: =E11*H11 -> 0.4725 | J11: =C11*H11 -> 0.378
A12: alho batido | C12: 0.02 | D12: 0 | E12: 0.02 | F12: KG | G12: =C12/E12 -> 1 | H12: 20.5 | I12: =E12*H12 -> 0.41 | J12: =C12*H12 -> 0.41
A13: sal com pimenta | C13: 0.005 | D13: 0 | E13: 0.005 | F13: KG | G13: =C13/E13 -> 1 | H13: 2.72 | I13: =E13*H13 -> 0.0136 | J13: =C13*H13 -> 0.0136
A14: Leitosa de empanamento | C14: 0.02 | D14: 0 | E14: 0.02 | G14: =C14/E14 -> 1 | H14: 7.25 | I14: =E14*H14 -> 0.145 | J14: =C14*H14 -> 0.145
A15: Farinha de trigo | C15: 0.01 | D15: 0 | E15: 0.01 | F15: KG | G15: =C15/E15 -> 1 | H15: 5.9 | I15: =E15*H15 -> 0.059 | J15: =C15*H15 -> 0.059
A16: Farinha panko | C16: 0.02 | D16: 0 | E16: 0.02 | F16: KG | G16: =C16/E16 -> 1 | H16: 16.2 | I16: =E16*H16 -> 0.324 | J16: =C16*H16 -> 0.324
A17: óleo de soja | C17: 0.02 | D17: 0 | E17: 0.02 | F17: L | G17: =C17/E17 -> 1 | H17: 7.89 | I17: =E17*H17 -> 0.1578 | J17: =C17*H17 -> 0.1578
A18: TOTAL | C18: =SUM(C8:C17) -> 0.685 | E18: =SUM(E8:E17) -> 0.695 | F18: KG | H18: VALOR TOTAL | I18: =SUM(I8:I17) -> 5.4844 | J18: =SUM(J8:J17) -> 5.6787
C19: 0.02 | D19: 0 | E19: 0.02 | F19: L | G19: =C19/E19 -> 1 | I19: =E19*H19 -> 0
A20: TOTAL | C20: =SUM(C8:C19) -> 1.39 | D20: 0 | E20: =SUM(E8:E19) -> 1.41 | F20: KG | G20: =C20/E20 -> 0.9858156 | H20: VALOR TOTAL | I20: =SUM(I8:I19) -> 10.9688

Sheet FILÉ FRANGO FRITAS
A1: Categoria | C1: Executivo | G1: Custo total | I1: =I15 -> 5.6784 | J1: =J15 -> 5.8727
A2: Preparação | C2: FILÉ DE FRANGO COM FRITAS | G2: Custo porção | I2: =I1/C4 -> 5.6784 | J2: =J1/C4 -> 5.8727
A3: Rendimento (porções) | C3: =E15/C4 -> 0.695 | G3: Índice de custo | I3: 5 | J3: 5
A4: Peso Porção | C4: 1 | G4: Preço de venda | I4: =I2*I3 -> 28.392 | J4: =J2*J3 -> 29.3635
A5: Obs: | C5: Executivo Bar do Zeca | G5: CMV | I5: =I2/I4 -> 0.2 | J5: =J2/J4 -> 0.2
A7: Ingrediente | B7: Código SKU | C7: PesoBruto | D7: Perda manipulação | E7: Peso Líquido | F7: Unidade | G7: Fator de Correção | H7: Custo compra | I7: Valor produção | J7: Valor preço de custo
A8: filé de frango | C8: 0.17 | D8: 0 | E8: 0.15 | F8: KG | G8: =C8/E8 -> 1.1333333 | H8: 14.44 | I8: =E8*H8 -> 2.166 | J8: =C8*H8 -> 2.4548
A9: arroz branco pronto | C9: 0.2 | D9: 0 | E9: 0.2 | F9: KG | G9: =C9/E9 -> 1 | H9: 1.98 | I9: =E9*H9 -> 0.396 | J9: =C9*H9 -> 0.396
A10: batata frita | C10: 0.15 | D10: 0 | E10: 0.15 | F10: KG | G10: =C10/E10 -> 1 | H10: 13.75 | I10: =E10*H10 -> 2.0625 | J10: =C10*H10 -> 2.0625
A11: feijão pronto | C11: 0.12 | D11: 0 | E11: 0.15 | F11: KG | G11: =C11/E11 -> 0.8 | H11: 3.15 | I11: =E11*H11 -> 0.4725 | J11: =C11*H11 -> 0.378
A12: alho batido | C12: 0.02 | D12: 0 | E12: 0.02 | F12: KG | G12: =C12/E12 -> 1 | H12: 20.5 | I12: =E12*H12 -> 0.41 | J12: =C12*H12 -> 0.41
A13: sal com pimenta | C13: 0.005 | D13: 0 | E13: 0.005 | F13: KG | G13: =C13/E13 -> 1 | H13: 2.72 | I13: =E13*H13 -> 0.0136 | J13: =C13*H13 -> 0.0136
A14: óleo de soja | C14: 0.02 | D14: 0 | E14: 0.02 | F14: L | G14: =C14/E14 -> 1 | H14: 7.89 | I14: =E14*H14 -> 0.1578 | J14: =C14*H14 -> 0.1578
A15: TOTAL | C15: =SUM(C8:C14) -> 0.685 | E15: =SUM(E8:E14) -> 0.695 | F15: KG | H15: VALOR TOTAL | I15: =SUM(I8:I14) -> 5.6784 | J15: =SUM(J8:J14) -> 5.8727
C16: 0.02 | D16: 0 | E16: 0.02 | F16: L | G16: =C16/E16 -> 1 | I16: =E16*H16 -> 0
A17: TOTAL | C17: =SUM(C8:C16) -> 1.39 | D17: 0 | E17: =SUM(E8:E16) -> 1.41 | F17: KG | G17: =C17/E17 -> 0.9858156 | H17: VALOR TOTAL | I17: =SUM(I8:I16) -> 11.3568

Sheet FILÉ DE FRANGO COM LEGUMES
A1: Categoria | C1: Executivo | G1: Custo total | I1: =I15 -> 6.1206826 | J1: =J15 -> 7.1034
A2: Preparação | C2: FILÉ DE FRANGO COM LEGUMES | G2: Custo porção | I2: =I1/C4 -> 6.1206826 | J2: =J1/C4 -> 7.1034
A3: Rendimento (porções) | C3: =E15/C4 -> 0.695 | G3: Índice de custo | I3: 5 | J3: 5
A4: Peso Porção | C4: 1 | G4: Preço de venda | I4: =I2*I3 -> 30.603413 | J4: =J2*J3 -> 35.517
A5: Obs: | C5: Executivo Bar do Zeca | G5: CMV | I5: =I2/I4 -> 0.2 | J5: =J2/J4 -> 0.2
A7: Ingrediente | B7: Código SKU | C7: PesoBruto | D7: Perda manipulação | E7: Peso Líquido | F7: Unidade | G7: Fator de Correção | H7: Custo compra | I7: Valor produção | J7: Valor preço de custo
A8: filé de frango | C8: 0.15 | D8: 0 | E8: 0.15 | F8: KG | G8: =C8/E8 -> 1 | H8: 14.44 | I8: =C8*H8 -> 2.166 | J8: =C8*H8 -> 2.166
A9: arroz branco pronto | C9: 0.2 | D9: 0 | E9: 0.2 | F9: KG | G9: =C9/E9 -> 1 | H9: 1.98 | I9: =E9*H9 -> 0.396 | J9: =C9*H9 -> 0.396
A10: salada de legumes | C10: 0.15 | D10: 0 | E10: 0.15 | F10: KG | G10: =C10/E10 -> 1 | H10: =I21 -> 16.698551 | I10: =E10*H10 -> 2.5047826 | J10: =C10*23.88 -> 3.582
A11: feijão pronto | C11: 0.12 | D11: 0 | E11: 0.15 | F11: KG | G11: =C11/E11 -> 0.8 | H11: 3.15 | I11: =E11*H11 -> 0.4725 | J11: =C11*H11 -> 0.378
A12: alho batido | C12: 0.02 | D12: 0 | E12: 0.02 | F12: KG | G12: =C12/E12 -> 1 | H12: 20.5 | I12: =E12*H12 -> 0.41 | J12: =C12*H12 -> 0.41
A13: sal com pimenta | C13: 0.005 | D13: 0 | E13: 0.005 | F13: KG | G13: =C13/E13 -> 1 | H13: 2.72 | I13: =E13*H13 -> 0.0136 | J13: =C13*H13 -> 0.0136
A14: óleo de soja | C14: 0.02 | D14: 0 | E14: 0.02 | F14: L | G14: =C14/E14 -> 1 | H14: 7.89 | I14: =E14*H14 -> 0.1578 | J14: =C14*H14 -> 0.1578
A15: TOTAL | C15: =SUM(C8:C14) -> 0.665 | E15: =SUM(E8:E14) -> 0.695 | F15: KG | H15: VALOR TOTAL | I15: =SUM(I8:I14) -> 6.1206826 | J15: =SUM(J8:J14) -> 7.1034
C16: 0.02 | D16: 0 | E16: 0.02 | F16: L | G16: =C16/E16 -> 1 | I16: =E16*H16 -> 0
C17: =SUM(C8:C16) -> 1.35 | D17: 0 | E17: =SUM(E8:E16) -> 1.41 | F17: KG | G17: =C17/E17 -> 0.95744681 | H17: VALOR TOTAL | I17: =SUM(I8:I16) -> 12.241365
A20: Categoria | C20: Executivo | G20: Custo total | I20: =I34 -> 17.283 | J20: =J34 -> 23.883
A21: Preparação | C21: SALADA DE LEGUMES MP | G21: Custo porção | I21: =I20/C23 -> 16.698551 | J21: =J20/C23 -> 23.075362
A22: Rendimento (porções) | C22: 1 | G22: Índice de custo | I22: 5 | J22: 5
A23: Peso Porção | C23: =E34/C22 -> 1.035 | G23: Preço de venda | I23: =I21*I22 -> 83.492754 | J23: =J21*J22 -> 115.37681
A24: Obs: | C24: Executivo Bar do Zeca | G24: CMV | I24: =I21/I23 -> 0.2 | J24: =J21/J23 -> 0.2
A26: Ingrediente | B26: Código SKU | C26: PesoBruto | D26: Perda manipulação | E26: Peso Líquido | F26: Unidade | G26: Fator de Correção | H26: Custo compra | I26: Valor produção | J26: Valor preço de custo
A27: batata asterix | C27: 0.5 | D27: 0 | E27: 0.43 | F27: KG | G27: =C27/E27 -> 1.1627907 | H27: 7.15 | I27: =E27*H27 -> 3.0745 | J27: =C27*H27 -> 3.575
A28: cenoura | C28: 0.3 | D28: 0 | E28: 0.25 | F28: KG | G28: =C28/E28 -> 1.2 | H28: 6.99 | I28: =E28*H28 -> 1.7475 | J28: =C28*H28 -> 2.097
A29: brócolis americano | C29: 0.3 | D29: 0 | E29: 0.2 | F29: KG | G29: =C29/E29 -> 1.5 | H29: 47.5 | I29: =E29*H29 -> 9.5 | J29: =C29*H29 -> 14.25
A30: vagem | C30: 0.2 | D30: 0 | E30: 0.1 | F30: KG | G30: =C30/E30 -> 2 | H30: 10 | I30: =E30*H30 -> 1 | J30: =C30*H30 -> 2
A31: salsa picada | C31: 0.02 | D31: 0 | E31: 0.02 | F31: KG | G31: =C31/E31 -> 1 | H31: 25.67 | I31: =E31*H31 -> 0.5134 | J31: =C31*H31 -> 0.5134
A32: sal com pimenta | C32: 0.005 | D32: 0 | E32: 0.005 | F32: KG | G32: =C32/E32 -> 1 | H32: 2.72 | I32: =E32*H32 -> 0.0136 | J32: =C32*H32 -> 0.0136
A33: azeite | C33: 0.03 | D33: 0 | E33: 0.03 | F33: L | G33: =C33/E33 -> 1 | H33: 47.8 | I33: =E33*H33 -> 1.434 | J33: =C33*H33 -> 1.434
A34: TOTAL | C34: =SUM(C27:C33) -> 1.355 | E34: =SUM(E27:E33) -> 1.035 | F34: KG | H34: VALOR TOTAL | I34: =SUM(I27:I33) -> 17.283 | J34: =SUM(J27:J33) -> 23.883
C35: 0.02 | D35: 0 | E35: 0.02 | F35: L | G35: =C35/E35 -> 1 | I35: =E35*H35 -> 0

Sheet FILÉ DE PEIXE COM LEGUMES
A1: Categoria | C1: Executivo | G1: Custo total | I1: =I15 -> 9.1026826 | J1: =J15 -> 11.3724
A2: Preparação | C2: FILÉ DE PEIXE COM LEGUMES | G2: Custo porção | I2: =I1/C4 -> 9.1026826 | J2: =J1/C4 -> 11.3724
A3: Rendimento (porções) | C3: =E15/C4 -> 0.665 | G3: Índice de custo | I3: 5 | J3: 5
A4: Peso Porção | C4: 1 | G4: Preço de venda | I4: =I2*I3 -> 45.513413 | J4: =J2*J3 -> 56.862
A5: Obs: | C5: Executivo Bar do Zeca | G5: CMV | I5: =I2/I4 -> 0.2 | J5: =J2/J4 -> 0.2
A7: Ingrediente | B7: Código SKU | C7: PesoBruto | D7: Perda manipulação | E7: Peso Líquido | F7: Unidade | G7: Fator de Correção | H7: Custo compra | I7: Valor produção | J7: Valor preço de custo
A8: filé de tilápia | C8: 0.15 | D8: 0 | E8: 0.12 | F8: KG | G8: =C8/E8 -> 1.25 | H8: 42.9 | I8: =E8*H8 -> 5.148 | J8: =C8*H8 -> 6.435
A9: arroz branco pronto | C9: 0.2 | D9: 0 | E9: 0.2 | F9: KG | G9: =C9/E9 -> 1 | H9: 1.98 | I9: =E9*H9 -> 0.396 | J9: =C9*H9 -> 0.396
A10: salada de legumes | C10: 0.15 | D10: 0 | E10: 0.15 | F10: KG | G10: =C10/E10 -> 1 | H10: =I21 -> 16.698551 | I10: =E10*H10 -> 2.5047826 | J10: =C10*23.88 -> 3.582
A11: feijão pronto | C11: 0.12 | D11: 0 | E11: 0.15 | F11: KG | G11: =C11/E11 -> 0.8 | H11: 3.15 | I11: =E11*H11 -> 0.4725 | J11: =C11*H11 -> 0.378
A12: alho batido | C12: 0.02 | D12: 0 | E12: 0.02 | F12: KG | G12: =C12/E12 -> 1 | H12: 20.5 | I12: =E12*H12 -> 0.41 | J12: =C12*H12 -> 0.41
A13: sal com pimenta | C13: 0.005 | D13: 0 | E13: 0.005 | F13: KG | G13: =C13/E13 -> 1 | H13: 2.72 | I13: =E13*H13 -> 0.0136 | J13: =C13*H13 -> 0.0136
A14: óleo de soja | C14: 0.02 | D14: 0 | E14: 0.02 | F14: L | G14: =C14/E14 -> 1 | H14: 7.89 | I14: =E14*H14 -> 0.1578 | J14: =C14*H14 -> 0.1578
A15: TOTAL | C15: =SUM(C8:C14) -> 0.665 | E15: =SUM(E8:E14) -> 0.665 | F15: KG | H15: VALOR TOTAL | I15: =SUM(I8:I14) -> 9.1026826 | J15: =SUM(J8:J14) -> 11.3724
C16: 0.02 | D16: 0 | E16: 0.02 | F16: L | G16: =C16/E16 -> 1 | I16: =E16*H16 -> 0
C17: =SUM(C8:C16) -> 1.35 | D17: 0 | E17: =SUM(E8:E16) -> 1.35 | F17: KG | G17: =C17/E17 -> 1 | H17: VALOR TOTAL | I17: =SUM(I8:I16) -> 18.205365
A20: Categoria | C20: Executivo | G20: Custo total | I20: =I34 -> 17.283 | J20: =J34 -> 23.883
A21: Preparação | C21: SALADA DE LEGUMES MP | G21: Custo porção | I21: =I20/C23 -> 16.698551 | J21: =J20/C23 -> 23.075362
A22: Rendimento (porções) | C22: 1 | G22: Índice de custo | I22: 5 | J22: 5
A23: Peso Porção | C23: =E34/C22 -> 1.035 | G23: Preço de venda | I23: =I21*I22 -> 83.492754 | J23: =J21*J22 -> 115.37681
A24: Obs: | C24: Executivo Bar do Zeca | G24: CMV | I24: =I21/I23 -> 0.2 | J24: =J21/J23 -> 0.2
A26: Ingrediente | B26: Código SKU | C26: PesoBruto | D26: Perda manipulação | E26: Peso Líquido | F26: Unidade | G26: Fator de Correção | H26: Custo compra | I26: Valor produção | J26: Valor preço de custo
A27: batata asterix | C27: 0.5 | D27: 0 | E27: 0.43 | F27: KG | G27: =C27/E27 -> 1.1627907 | H27: 7.15 | I27: =E27*H27 -> 3.0745 | J27: =C27*H27 -> 3.575
A28: cenoura | C28: 0.3 | D28: 0 | E28: 0.25 | F28: KG | G28: =C28/E28 -> 1.2 | H28: 6.99 | I28: =E28*H28 -> 1.7475 | J28: =C28*H28 -> 2.097
A29: brócolis americano | C29: 0.3 | D29: 0 | E29: 0.2 | F29: KG | G29: =C29/E29 -> 1.5 | H29: 47.5 | I29: =E29*H29 -> 9.5 | J29: =C29*H29 -> 14.25
A30: vagem | C30: 0.2 | D30: 0 | E30: 0.1 | F30: KG | G30: =C30/E30 -> 2 | H30: 10 | I30: =E30*H30 -> 1 | J30: =C30*H30 -> 2
A31: salsa picada | C31: 0.02 | D31: 0 | E31: 0.02 | F31: KG | G31: =C31/E31 -> 1 | H31: 25.67 | I31: =E31*H31 -> 0.5134 | J31: =C31*H31 -> 0.5134
A32: sal com pimenta | C32: 0.005 | D32: 0 | E32: 0.005 | F32: KG | G32: =C32/E32 -> 1 | H32: 2.72 | I32: =E32*H32 -> 0.0136 | J32: =C32*H32 -> 0.0136
A33: azeite | C33: 0.03 | D33: 0 | E33: 0.03 | F33: L | G33: =C33/E33 -> 1 | H33: 47.8 | I33: =E33*H33 -> 1.434 | J33: =C33*H33 -> 1.434
A34: TOTAL | C34: =SUM(C27:C33) -> 1.355 | E34: =SUM(E27:E33) -> 1.035 | F34: KG | H34: VALOR TOTAL | I34: =SUM(I27:I33) -> 17.283 | J34: =SUM(J27:J33) -> 23.883
C35: 0.02 | D35: 0 | E35: 0.02 | F35: L | G35: =C35/E35 -> 1 | I35: =E35*H35 -> 0

Sheet FILÉ DE PEIXE COM PURÊ
A1: Categoria | C1: Executivo | G1: Custo total | I1: =I15 -> 9.2894 | J1: =J15 -> 10.4819
A2: Preparação | C2: FILÉ DE PEIXE COM LEGUMES | G2: Custo porção | I2: =I1/C4 -> 9.2894 | J2: =J1/C4 -> 10.4819
A3: Rendimento (porções) | C3: =E15/C4 -> 0.665 | G3: Índice de custo | I3: 5 | J3: 5
A4: Peso Porção | C4: 1 | G4: Preço de venda | I4: =I2*I3 -> 46.447 | J4: =J2*J3 -> 52.4095
A5: Obs: | C5: Executivo Bar do Zeca | G5: CMV | I5: =I2/I4 -> 0.2 | J5: =J2/J4 -> 0.2
A7: Ingrediente | B7: Código SKU | C7: PesoBruto | D7: Perda manipulação | E7: Peso Líquido | F7: Unidade | G7: Fator de Correção | H7: Custo compra | I7: Valor produção | J7: Valor preço de custo
A8: filé de tilápia | C8: 0.15 | D8: 0 | E8: 0.12 | F8: KG | G8: =C8/E8 -> 1.25 | H8: 42.9 | I8: =E8*H8 -> 5.148 | J8: =C8*H8 -> 6.435
A9: arroz branco de brocolis mp | C9: 0.2 | D9: 0 | E9: 0.2 | F9: KG | G9: =C9/E9 -> 1 | H9: 8.83 | I9: =E9*H9 -> 1.766 | J9: =C9*H9 -> 1.766
A10: purê de batata mp | C10: 0.15 | D10: 0 | E10: 0.15 | F10: KG | G10: =C10/E10 -> 1 | H10: 8.81 | I10: =E10*H10 -> 1.3215 | J10: =C10*H10 -> 1.3215
A11: feijão pronto | C11: 0.12 | D11: 0 | E11: 0.15 | F11: KG | G11: =C11/E11 -> 0.8 | H11: 3.15 | I11: =E11*H11 -> 0.4725 | J11: =C11*H11 -> 0.378
A12: alho batido | C12: 0.02 | D12: 0 | E12: 0.02 | F12: KG | G12: =C12/E12 -> 1 | H12: 20.5 | I12: =E12*H12 -> 0.41 | J12: =C12*H12 -> 0.41
A13: sal com pimenta | C13: 0.005 | D13: 0 | E13: 0.005 | F13: KG | G13: =C13/E13 -> 1 | H13: 2.72 | I13: =E13*H13 -> 0.0136 | J13: =C13*H13 -> 0.0136
A14: óleo de soja | C14: 0.02 | D14: 0 | E14: 0.02 | F14: L | G14: =C14/E14 -> 1 | H14: 7.89 | I14: =E14*H14 -> 0.1578 | J14: =C14*H14 -> 0.1578
A15: TOTAL | C15: =SUM(C8:C14) -> 0.665 | E15: =SUM(E8:E14) -> 0.665 | F15: KG | H15: VALOR TOTAL | I15: =SUM(I8:I14) -> 9.2894 | J15: =SUM(J8:J14) -> 10.4819
C16: 0.02 | D16: 0 | E16: 0.02 | F16: L | G16: =C16/E16 -> 1 | I16: =E16*H16 -> 0
C17: =SUM(C8:C16) -> 1.35 | D17: 0 | E17: =SUM(E8:E16) -> 1.35 | F17: KG | G17: =C17/E17 -> 1 | H17: VALOR TOTAL | I17: =SUM(I8:I16) -> 18.5788

Sheet PERNIL COM MAIONESE
A1: Categoria | C1: Executivo | G1: Custo total | I1: =I14 -> 6.6397732 | J1: =J14 -> 6.7469
A2: Preparação | C2: PERNIL COM MAIONESE | G2: Custo porção | I2: =I1/C4 -> 6.6397732 | J2: =J1/C4 -> 6.7469
A3: Rendimento (porções) | C3: =E14/C4 -> 0.595 | G3: Índice de custo | I3: 5 | J3: 5
A4: Peso Porção | C4: 1 | G4: Preço de venda | I4: =I2*I3 -> 33.198866 | J4: =J2*J3 -> 33.7345
A5: Obs: | C5: Executivo Bar do Zeca | G5: CMV | I5: =I2/I4 -> 0.2 | J5: =J2/J4 -> 0.2
A7: Ingrediente | B7: Código SKU | C7: PesoBruto | D7: Perda manipulação | E7: Peso Líquido | F7: Unidade | G7: Fator de Correção | H7: Custo compra | I7: Valor produção | J7: Valor preço de custo
A8: Pernil MP | C8: 0.12 | D8: 0 | E8: 0.12 | F8: KG | G8: =C8/E8 -> 1 | H8: 36.99 | I8: =E8*H8 -> 4.4388 | J8: =C8*H8 -> 4.4388
A9: arroz branco pronto | C9: 0.2 | D9: 0 | E9: 0.2 | F9: KG | G9: =C9/E9 -> 1 | H9: 1.98 | I9: =E9*H9 -> 0.396 | J9: =C9*H9 -> 0.396
A10: Salada de Maionese MP | C10: 0.1 | D10: 0 | E10: 0.1 | F10: KG | G10: =C10/E10 -> 1 | H10: =I20 -> 9.6987324 | I10: =E10*H10 -> 0.96987324 | J10: =C10*10.77 -> 1.077
A11: feijão pronto | C11: 0.12 | D11: 0 | E11: 0.12 | F11: KG | G11: =C11/E11 -> 1 | H11: 3.15 | I11: =E11*H11 -> 0.378 | J11: =C11*H11 -> 0.378
A12: farofa de bacon | C12: 0.05 | D12: 0 | E12: 0.05 | F12: KG | G12: =C12/E12 -> 1 | H12: 8.87 | I12: =E12*H12 -> 0.4435 | J12: =C12*H12 -> 0.4435
A13: sal com pimenta | C13: 0.005 | D13: 0 | E13: 0.005 | F13: KG | G13: =C13/E13 -> 1 | H13: 2.72 | I13: =E13*H13 -> 0.0136 | J13: =C13*H13 -> 0.0136
A14: TOTAL | C14: =SUM(C8:C13) -> 0.595 | E14: =SUM(E8:E13) -> 0.595 | F14: KG | H14: VALOR TOTAL | I14: =SUM(I8:I13) -> 6.6397732 | J14: =SUM(J8:J13) -> 6.7469
C15: 0.02 | D15: 0 | E15: 0.02 | F15: L | G15: =C15/E15 -> 1 | I15: =E15*H15 -> 0
C16: =SUM(C8:C15) -> 1.21 | D16: 0 | E16: =SUM(E8:E15) -> 1.21 | F16: KG | G16: =C16/E16 -> 1 | H16: VALOR TOTAL | I16: =SUM(I8:I15) -> 13.279546
A19: Categoria | C19: Executivo | G19: Custo total | I19: =I32 -> 10.32915 | J19: =J32 -> 11.46675
A20: Preparação | C20: SALADA DE MAIONESE | G20: Custo porção | I20: =I19/C22 -> 9.6987324 | J20: =J19/C22 -> 10.766901
A21: Rendimento (porções) | C21: 1 | G21: Índice de custo | I21: 5 | J21: 5
A22: Peso Porção | C22: =E32/C21 -> 1.065 | G22: Preço de venda | I22: =I20*I21 -> 48.493662 | J22: =J20*J21 -> 53.834507
A23: Obs: | C23: Executivo Bar do Zeca | G23: CMV | I23: =I20/I22 -> 0.2 | J23: =J20/J22 -> 0.2
A25: Ingrediente | B25: Código SKU | C25: PesoBruto | D25: Perda manipulação | E25: Peso Líquido | F25: Unidade | G25: Fator de Correção | H25: Custo compra | I25: Valor produção | J25: Valor preço de custo
A26: Batata asterix | C26: 0.75 | D26: 0 | E26: 0.63 | F26: KG | G26: =C26/E26 -> 1.1904762 | H26: 7.15 | I26: =E26*H26 -> 4.5045 | J26: =C26*H26 -> 5.3625
A27: cenoura | C27: 0.2 | D27: 0 | E27: 0.16 | F27: KG | G27: =C27/E27 -> 1.25 | H27: 6.99 | I27: =E27*H27 -> 1.1184 | J27: =C27*H27 -> 1.398
A28: alho batido | C28: 0.1 | D28: 0 | E28: 0.1 | F28: KG | G28: =C28/E28 -> 1 | H28: 20.5 | I28: =E28*H28 -> 2.05 | J28: =C28*H28 -> 2.05
A29: sal com pimenta | C29: 0.01 | D29: 0 | E29: 0.01 | F29: KG | G29: =C29/E29 -> 1 | H29: 2.72 | I29: =E29*H29 -> 0.0272 | J29: =C29*H29 -> 0.0272
A30: maionese | C30: 0.15 | D30: 0 | E30: 0.15 | F30: KG | G30: =C30/E30 -> 1 | H30: 14.96 | I30: =E30*H30 -> 2.244 | J30: =C30*H30 -> 2.244
A31: salsa picada | C31: 0.015 | D31: 0 | E31: 0.015 | F31: KG | G31: =C31/E31 -> 1 | H31: 25.67 | I31: =E31*H31 -> 0.38505 | J31: =C31*H31 -> 0.38505
A32: TOTAL | C32: =SUM(C26:C31) -> 1.225 | E32: =SUM(E26:E31) -> 1.065 | F32: KG | H32: VALOR TOTAL | I32: =SUM(I26:I31) -> 10.32915 | J32: =SUM(J26:J31) -> 11.46675
C33: 0.02 | D33: 0 | E33: 0.02 | F33: L | G33: =C33/E33 -> 1 | I33: =E33*H33 -> 0

Sheet SCHNITZEL COM MAIONESE
A1: Categoria | C1: Executivo | G1: Custo total | I1: =I18 -> 4.2184732 | J1: =J18 -> 4.665
A2: Preparação | C2: SCHNITIZEL COM MAIONESE | G2: Custo porção | I2: =I1/C4 -> 4.2184732 | J2: =J1/C4 -> 4.665
A3: Rendimento (porções) | C3: =E18/C4 -> 0.655 | G3: Índice de custo | I3: 5 | J3: 5
A4: Peso Porção | C4: 1 | G4: Preço de venda | I4: =I2*I3 -> 21.092366 | J4: =J2*J3 -> 23.325
A5: Obs: | C5: Executivo Bar do Zeca | G5: CMV | I5: =I2/I4 -> 0.2 | J5: =J2/J4 -> 0.2
A7: Ingrediente | B7: Código SKU | C7: PesoBruto | D7: Perda manipulação | E7: Peso Líquido | F7: Unidade | G7: Fator de Correção | H7: Custo compra | I7: Valor produção | J7: Valor preço de custo
A8: copalombo | C8: 0.12 | D8: 0 | E8: 0.1 | F8: KG | G8: =C8/E8 -> 1.2 | H8: 16.97 | I8: =E8*H8 -> 1.697 | J8: =C8*H8 -> 2.0364
A9: arroz branco pronto | C9: 0.2 | D9: 0 | E9: 0.2 | F9: KG | G9: =C9/E9 -> 1 | H9: 1.98 | I9: =E9*H9 -> 0.396 | J9: =C9*H9 -> 0.396
A10: Salada de maionese MP | C10: 0.1 | D10: 0 | E10: 0.1 | F10: KG | G10: =C10/E10 -> 1 | H10: =I24 -> 9.6987324 | I10: =E10*H10 -> 0.96987324 | J10: =C10*10.77 -> 1.077
A11: feijão pronto | C11: 0.12 | D11: 0 | E11: 0.12 | F11: KG | G11: =C11/E11 -> 1 | H11: 3.15 | I11: =E11*H11 -> 0.378 | J11: =C11*H11 -> 0.378
A12: farinha de trigo | C12: 0.05 | D12: 0 | E12: 0.05 | F12: KG | G12: =C12/E12 -> 1 | H12: 5.9 | I12: =E12*H12 -> 0.295 | J12: =C12*H12 -> 0.295
A13: farinha panko | C13: 0.02 | D13: 0 | E13: 0.02 | F13: KG | G13: =C13/E13 -> 1 | H13: 16.2 | I13: =E13*H13 -> 0.324 | J13: =C13*H13 -> 0.324
A14: leitosa de empanamento | C14: 0.02 | D14: 0 | E14: 0.02 | F14: KG | G14: 1 | H14: 7.25 | I14: =E14*H14 -> 0.145 | J14: =C14*H14 -> 0.145
A15: sal com pimenta | C15: 0.005 | D15: 0 | E15: 0.005 | F15: KG | G15: =C15/E15 -> 1 | H15: 2.72 | I15: =E15*H15 -> 0.0136 | J15: =C15*H15 -> 0.0136
A16: alho batido | C16: 0.02 | D16: 0 | E16: 0.02 | F16: KG | G16: 1 | H16: 20.5 | I16: =E16*H16 -> 0.41 | J16: =C16*H16 -> 0.41
A17: limão sciciliano | C17: 0.02 | D17: 0 | E17: 0.02 | F17: kg | G17: 1 | H17: 9.61 | I17: =E17*H17 -> 0.1922 | J17: =C17*H17 -> 0.1922
A18: TOTAL | C18: =SUM(C8:C17) -> 0.675 | E18: =SUM(E8:E17) -> 0.655 | F18: KG | H18: VALOR TOTAL | I18: =SUM(I8:I15) -> 4.2184732 | J18: =SUM(J8:J15) -> 4.665
C19: 0.02 | D19: 0 | E19: 0.02 | F19: L | G19: =C19/E19 -> 1 | I19: =E19*H19 -> 0
C20: =SUM(C8:C19) -> 1.37 | D20: 0 | E20: =SUM(E8:E19) -> 1.33 | F20: KG | G20: =C20/E20 -> 1.0300752 | H20: VALOR TOTAL | I20: =SUM(I8:I19) -> 9.0391465
A23: Categoria | C23: Executivo | G23: Custo total | I23: =I36 -> 10.32915 | J23: =J36 -> 11.46675
A24: Preparação | C24: SALADA DE MAIONESE | G24: Custo porção | I24: =I23/C26 -> 9.6987324 | J24: =J23/C26 -> 10.766901
A25: Rendimento (porções) | C25: 1 | G25: Índice de custo | I25: 5 | J25: 5
A26: Peso Porção | C26: =E36/C25 -> 1.065 | G26: Preço de venda | I26: =I24*I25 -> 48.493662 | J26: =J24*J25 -> 53.834507
A27: Obs: | C27: Executivo Bar do Zeca | G27: CMV | I27: =I24/I26 -> 0.2 | J27: =J24/J26 -> 0.2
A29: Ingrediente | B29: Código SKU | C29: PesoBruto | D29: Perda manipulação | E29: Peso Líquido | F29: Unidade | G29: Fator de Correção | H29: Custo compra | I29: Valor produção | J29: Valor preço de custo
A30: Batata asterix | C30: 0.75 | D30: 0 | E30: 0.63 | F30: KG | G30: =C30/E30 -> 1.1904762 | H30: 7.15 | I30: =E30*H30 -> 4.5045 | J30: =C30*H30 -> 5.3625
A31: cenoura | C31: 0.2 | D31: 0 | E31: 0.16 | F31: KG | G31: =C31/E31 -> 1.25 | H31: 6.99 | I31: =E31*H31 -> 1.1184 | J31: =C31*H31 -> 1.398
A32: alho batido | C32: 0.1 | D32: 0 | E32: 0.1 | F32: KG | G32: =C32/E32 -> 1 | H32: 20.5 | I32: =E32*H32 -> 2.05 | J32: =C32*H32 -> 2.05
A33: sal com pimenta | C33: 0.01 | D33: 0 | E33: 0.01 | F33: KG | G33: =C33/E33 -> 1 | H33: 2.72 | I33: =E33*H33 -> 0.0272 | J33: =C33*H33 -> 0.0272
A34: maionese | C34: 0.15 | D34: 0 | E34: 0.15 | F34: KG | G34: =C34/E34 -> 1 | H34: 14.96 | I34: =E34*H34 -> 2.244 | J34: =C34*H34 -> 2.244
A35: salsa picada | C35: 0.015 | D35: 0 | E35: 0.015 | F35: KG | G35: =C35/E35 -> 1 | H35: 25.67 | I35: =E35*H35 -> 0.38505 | J35: =C35*H35 -> 0.38505
A36: TOTAL | C36: =SUM(C30:C35) -> 1.225 | E36: =SUM(E30:E35) -> 1.065 | F36: KG | H36: VALOR TOTAL | I36: =SUM(I30:I35) -> 10.32915 | J36: =SUM(J30:J35) -> 11.46675
C37: 0.02 | D37: 0 | E37: 0.02 | F37: L | G37: =C37/E37 -> 1 | I37: =E37*H37 -> 0

Sheet GNOCCHI COM CARNE ASSADA
A1: Categoria | C1: Executivo | G1: Custo total | I1: =I14 -> 12.922429 | J1: =J14 -> 12.922429
A2: Preparação | C2: GNOCCHI COM CARNE ASSADA | G2: Custo porção | I2: =I1/C4 -> 12.922429 | J2: =J1/C4 -> 12.922429
A3: Rendimento (porções) | C3: =E14/C4 -> 1.375 | G3: Índice de custo | I3: 5 | J3: 5
A4: Peso Porção | C4: 1 | G4: Preço de venda | I4: =I2*I3 -> 64.612145 | J4: =J2*J3 -> 64.612145
A5: Obs: | C5: Executivo Bar do Zeca | G5: CMV | I5: =I2/I4 -> 0.2 | J5: =J2/J4 -> 0.2
A7: Ingrediente | B7: Código SKU | C7: PesoBruto | D7: Perda manipulação | E7: Peso Líquido | F7: Unidade | G7: Fator de Correção | H7: Custo compra | I7: Valor produção | J7: Valor preço de custo
A8: Carne assada 120gr | C8: 1 | E8: 1 | F8: KG | G8: =C8/E8 -> 1 | H8: 7.97 | I8: =E8*H8 -> 7.97 | J8: =C8*H8 -> 7.97
A9: Base de gnocchi | C9: 0.25 | E9: 0.25 | F9: KG | G9: =C9/E9 -> 1 | H9: =J20 -> 12.702316 | I9: =E9*H9 -> 3.1755789 | J9: =C9*H9 -> 3.1755789
A10: Molho ao sugo | C10: 0.05 | E10: 0.05 | F10: KG | G10: =C10/E10 -> 1 | H10: 10.83 | I10: =E10*H10 -> 0.5415 | J10: =C10*H10 -> 0.5415
A11: Parmesão | C11: 0.02 | E11: 0.02 | F11: KG | G11: =C11/E11 -> 1 | H11: 48.5 | I11: =E11*H11 -> 0.97 | J11: =C11*H11 -> 0.97
A12: Caldo de carne | C12: 0.05 | E12: 0.05 | F12: KG | G12: =C12/E12 -> 1 | H12: 3.04 | I12: =E12*H12 -> 0.152 | J12: =C12*H12 -> 0.152
A13: Manjericão | C13: 0.005 | E13: 0.005 | F13: KG | G13: =C13/E13 -> 1 | H13: 22.67 | I13: =E13*H13 -> 0.11335 | J13: =C13*H13 -> 0.11335
A14: TOTAL | C14: =SUM(C8:C13) -> 1.375 | E14: =SUM(E8:E13) -> 1.375 | F14: KG | H14: VALOR TOTAL | I14: =SUM(I8:I13) -> 12.922429 | J14: =SUM(J8:J13) -> 12.922429
C15: 0.02 | D15: 0 | E15: 0.02 | F15: L | G15: =C15/E15 -> 1 | I15: =E15*H15 -> 0
C16: =SUM(C8:C15) -> 2.77 | D16: 0 | E16: =SUM(E8:E15) -> 2.77 | F16: KG | G16: =C16/E16 -> 1 | H16: VALOR TOTAL | I16: =SUM(I8:I15) -> 25.844858
A19: Categoria | C19: Executivo | G19: Custo total | I19: =I32 -> 13.3181 | J19: =J32 -> 18.1008
A20: Preparação | C20: BASE DE GNOCCHI | G20: Custo porção | I20: =I19/C22 -> 9.3460351 | J20: =J19/C22 -> 12.702316
A21: Rendimento (porções) | C21: 1 | G21: Índice de custo | I21: 5 | J21: 5
A22: Peso Porção | C22: =E32/C21 -> 1.425 | G22: Preço de venda | I22: =I20*I21 -> 46.730175 | J22: =J20*J21 -> 63.511579
A23: Obs: | C23: Executivo Bar do Zeca | G23: CMV | I23: =I20/I22 -> 0.2 | J23: =J20/J22 -> 0.2
A25: Ingrediente | B25: Código SKU | C25: PesoBruto | D25: Perda manipulação | E25: Peso Líquido | F25: Unidade | G25: Fator de Correção | H25: Custo compra | I25: Valor produção | J25: Valor preço de custo
A26: Batata asterix | C26: 1 | E26: 0.83 | F26: KG | G26: =C26/E26 -> 1.2048193 | H26: 7.15 | I26: =E26*H26 -> 5.9345 | J26: =C26*H26 -> 7.15
A27: Ovo branco | C27: 7 | E27: 0.14 | F27: KG | G27: =C27/E27 -> 50 | H27: 0.52 | I27: =E27*H27 -> 0.0728 | J27: =C27*H27 -> 3.64
A28: Farinha de trigo | C28: 0.275 | E28: 0.275 | F28: KG | G28: =C28/E28 -> 1 | H28: 5.9 | I28: =E28*H28 -> 1.6225 | J28: =C28*H28 -> 1.6225
A29: Sal refinado | C29: 0.015 | E29: 0.015 | F29: KG | G29: =C29/E29 -> 1 | H29: 2.72 | I29: =E29*H29 -> 0.0408 | J29: =C29*H29 -> 0.0408
A30: Manteiga | C30: 0.15 | E30: 0.15 | F30: KG | G30: =C30/E30 -> 1 | H30: 32.8 | I30: =E30*H30 -> 4.92 | J30: =C30*H30 -> 4.92
A31: Parmesão | C31: 0.015 | E31: 0.015 | F31: KG | G31: =C31/E31 -> 1 | H31: 48.5 | I31: =E31*H31 -> 0.7275 | J31: =C31*H31 -> 0.7275
A32: TOTAL | C32: =SUM(C26:C31) -> 8.455 | E32: =SUM(E26:E31) -> 1.425 | F32: KG | H32: VALOR TOTAL | I32: =SUM(I26:I31) -> 13.3181 | J32: =SUM(J26:J31) -> 18.1008
C33: 0.02 | D33: 0 | E33: 0.02 | F33: L | G33: =C33/E33 -> 1 | I33: =E33*H33 -> 0

Sheet Resumo
A1: PREÇO DE CUSTO
B2: Custo bruto | C2: Indíce de custo 3 | D2: Indíce de custo 3,5 | E2: Indíce de custo 4 | F2: Indíce de custo 4,5 | G2: Indíce de custo 5
A3: EMPADÃO DE FRANGO COM SALADA | B3: ='EMPADÃO DE FRANGO COM SALADA '!J2 -> 7.0184 | C3: =B3*3 -> 21.0552 | D3: =B3*3.5 -> 24.5644 | E3: =B3*4 -> 28.0736 | F3: =B3*4.5 -> 31.5828 | G3: =B3*5 -> 35.092
A4: MINI ORELHA EXECUTIVO | B4: ='MINI ORELHA EXECUTIVO'!J2 -> 9.9136 | C4: =B4*3 -> 29.7408 | D4: =B4*3.5 -> 34.6976 | E4: =B4*4 -> 39.6544 | F4: =B4*4.5 -> 44.6112 | G4: =B4*5 -> 49.568
A5: CARNE GUISADA COM BATATA CORADA | B5: ='CARNE GUISADA COM BATATA CORAD'!J2 -> 8.9211 | C5: =B5*3 -> 26.7633 | D5: =B5*3.5 -> 31.22385 | E5: =B5*4 -> 35.6844 | F5: =B5*4.5 -> 40.14495 | G5: =B5*5 -> 44.6055
A6: CARNE SECA COM TUTU À MINEIRA | B6: ='CARNE SECA COM TUTU À MINEIRA'!J2 -> 17.133727 | C6: =B6*3 -> 51.401182 | D6: =B6*3.5 -> 59.968046 | E6: =B6*4 -> 68.53491 | F6: =B6*4.5 -> 77.101773 | G6: =B6*5 -> 85.668637
A7: ISCA DE FÍGADO COM PURÊ | B7: ='ISCA DE FÍGADO COM PURÊ'!J2 -> 5.48615 | C7: =B7*3 -> 16.45845 | D7: =B7*3.5 -> 19.201525 | E7: =B7*4 -> 21.9446 | F7: =B7*4.5 -> 24.687675 | G7: =B7*5 -> 27.43075
A8: FILÉ FRANGO EMPANADO COM FRITAS | B8: ='FILÉ FRANGO EMPANADO COM FRITAS'!J2 -> 5.6787 | C8: =B8*3 -> 17.0361 | D8: =B8*3.5 -> 19.87545 | E8: =B8*4 -> 22.7148 | F8: =B8*4.5 -> 25.55415 | G8: =B8*5 -> 28.3935
A9: FILÉ FRANGO FRITAS | B9: ='FILÉ FRANGO FRITAS'!J2 -> 5.8727 | C9: =B9*3 -> 17.6181 | D9: =B9*3.5 -> 20.55445 | E9: =B9*4 -> 23.4908 | F9: =B9*4.5 -> 26.42715 | G9: =B9*5 -> 29.3635
A10: FILÉ DE FRANGO COM LEGUMES | B10: ='FILÉ DE FRANGO COM LEGUMES'!J2 -> 7.1034 | C10: =B10*3 -> 21.3102 | D10: =B10*3.5 -> 24.8619 | E10: =B10*4 -> 28.4136 | F10: =B10*4.5 -> 31.9653 | G10: =B10*5 -> 35.517
A11: FILÉ DE PEIXE COM LEGUMES | B11: ='FILÉ DE PEIXE COM LEGUMES'!J2 -> 11.3724 | C11: =B11*3 -> 34.1172 | D11: =B11*3.5 -> 39.8034 | E11: =B11*4 -> 45.4896 | F11: =B11*4.5 -> 51.1758 | G11: =B11*5 -> 56.862
A12: FILÉ DE PEIXE COM PURÊ | B12: ='FILÉ DE PEIXE COM PURÊ'!J2 -> 10.4819 | C12: =B12*3 -> 31.4457 | D12: =B12*3.5 -> 36.68665 | E12: =B12*4 -> 41.9276 | F12: =B12*4.5 -> 47.16855 | G12: =B12*5 -> 52.4095
A13: PERNIL COM MAIONESE | B13: ='PERNIL COM MAIONESE'!J2 -> 6.7469 | C13: =B13*3 -> 20.2407 | D13: =B13*3.5 -> 23.61415 | E13: =B13*4 -> 26.9876 | F13: =B13*4.5 -> 30.36105 | G13: =B13*5 -> 33.7345
A14: SCHNITZEL COM MAIONESE | B14: ='SCHNITZEL COM MAIONESE'!J2 -> 4.665 | C14: =B14*3 -> 13.995 | D14: =B14*3.5 -> 16.3275 | E14: =B14*4 -> 18.66 | F14: =B14*4.5 -> 20.9925 | G14: =B14*5 -> 23.325
A15: GNOCCHI COM CARNE ASSADA | B15: ='GNOCCHI COM CARNE ASSADA'!J2 -> 12.922429 | C15: =B15*3 -> 38.767287 | D15: =B15*3.5 -> 45.228501 | E15: =B15*4 -> 51.689716 | F15: =B15*4.5 -> 58.15093 | G15: =B15*5 -> 64.612145
